Workbook

Sheet 전체 일정
A1: 한 달, 800km 나를 되찾는 53개의 쉼표 그리고 새로운 시작
A2: 도카이도 도보 여행 · 2026.12.4 ~ 2027.1.3 · 시나가와 → 하코네 → 교토 산조오하시 → 아리마 온천 → 오사카
A4: 일차 | B4: 날짜 | C4: 요일 | D4: 권역 | E4: 숙박 지역 | F4: 박수 | G4: 구분 | H4: 걷는 거리 (지도) | I4: 걷는 시간 | J4: 출발(예상) | K4: 도착(예상) | L4: 해 지기 전 여유 | M4: 하루 성격 | N4: 지나는 역참 | O4: 이동 순서 (교통·걷기·관광) | Q4: 일차 | R4: 날짜 | S4: 권역 | T4: 숙박 지역 | U4: 명소 (꼭 갈 곳·온천) | V4: 먹거리 | W4: 특산품·공예·산업 | X4: 역사적 배경 | Y4: 지금의 모습 (어떤 도시인가) | Z4: 메모
A5: 1 | B5: 12/4 | C5: 금 | D5: 도쿄 | E5: 도쿄 시나가와 | F5: 2박 | G5: 교통 | H5: =IF('이동 상세'!H6="","",'이동 상세'!H6) | I5: =IF('이동 상세'!H6="","",'이동 상세'!I6) | J5: =IF('이동 상세'!P6="","",'이동 상세'!P6) | K5: =IF('이동 상세'!Q6="","",'이동 상세'!Q6) | L5: =IF('이동 상세'!S6="","",'이동 상세'!S6) | M5: 도착 | N5: 1 시나가와 (숙박하며 구경) | O5: 교통)하네다공항역 → 시나가와역 (게이큐) | Q5: 1 | R5: 12/4 | S5: 도쿄 | T5: 도쿄 시나가와 | U5: 기타시나가와 옛 시나가와주쿠 거리 | X5: 도카이도 53역참 가운데 첫 번째 역참. 에도를 떠나는 사람과 배웅하는 사람으로 붐비던 곳. | Y5: 신칸센과 하네다공항으로 이어지는 도쿄 남쪽 관문이자 대기업 본사가 모인 업무 지구. 리니어 주오 신칸센의 출발역도 이곳에 짓고 있습니다. | Z5: 교통 이유: 공항에서 숙소로 가는 도착일 이동.
A6: 2 | B6: 12/5 | C6: 토 | D6: 도쿄 | E6: 도쿄 시나가와 | F6: ↑ | G6: 관광 | H6: =IF('이동 상세'!H7="","",'이동 상세'!H7) | I6: =IF('이동 상세'!H7="","",'이동 상세'!I7) | J6: =IF('이동 상세'!P7="","",'이동 상세'!P7) | K6: =IF('이동 상세'!Q7="","",'이동 상세'!Q7) | L6: =IF('이동 상세'!S7="","",'이동 상세'!S7) | M6: 도쿄 관광 | O6: 관광)도쿄 관광 (지하철) | Q6: 2 | R6: 12/5 | S6: 도쿄 | T6: 도쿄 시나가와 | U6: 니혼바시 (다리 한가운데 일본 도로 원점), 아사쿠사 센소지, 긴자 | V6: 쓰키지 장외시장: 초밥, 계란말이 | W6: 니혼바시 노포: 가쓰오부시 '닌벤', 김 '야마모토노리' | X6: 1603년 도쿠가와 이에야스가 놓은 다리로, 도카이도를 비롯한 5가도의 출발점. 지금 돌다리는 1911년에 놓였습니다. | Y6: 옛 상업 중심지이자 지금도 증권거래소와 은행 본점이 모인 금융가. 다리 위를 덮은 수도고속도로를 지하로 옮기는 공사가 진행 중입니다. | Z6: 교통 이유: 도쿄 시내 관광은 지하철이 편함.
A7: 3 | B7: 12/6 | C7: 일 | D7: 하코네·후지 | E7: 오다와라 | F7: 1박 | G7: 교통+걷기 | H7: =IF('이동 상세'!H8="","",HYPERLINK('경로 좌표'!N6,'이동 상세'!H8)) -> 16.9 | I7: =IF('이동 상세'!H8="","",'이동 상세'!I8) -> 0.17604167 | J7: =IF('이동 상세'!P8="","",'이동 상세'!P8) -> 0.35416667 | K7: =IF('이동 상세'!Q8="","",'이동 상세'!Q8) -> 0.571875 | L7: =IF('이동 상세'!S8="","",'이동 상세'!S8) -> 0.116235 | M7: 걷기 시작 | N7: 8 오이소 9 오다와라 | O7: 교통)시나가와역 → 오이소역 (JR 도카이도선) 걷기)오이소 → 오다와라 | Q7: 3 | R7: 12/6 | S7: 하코네·후지 | T7: 오다와라 | U7: 오이소 소나무 가로수길, 오다와라성 | V7: 오다와라역 주변: 가마보코 (어묵), 전갱이 덮밥 | W7: 오다와라: 가마보코 (어묵), 우메보시 (매실 장아찌), 오다와라 칠기 | X7: 전국시대 호조 가문의 본거지. 1590년 도요토미 히데요시가 오다와라성을 함락시키며 천하 통일을 마무리했습니다. | Y7: 신칸센이 서는 하코네 관광의 입구 도시. 오이소는 메이지 시대부터 총리 등 정치인의 별장지로 유명했습니다. | Z7: 교통 이유: 시나가와~오이소 약 60km는 가와사키·요코하마 도심과 국도 1호선 옆 길이 계속되어 볼거리가 적고 걷기 단조로움 (기차) 비올때: JR 도카이도선 니노미야·고즈·가모미야역에서 기차로 오다와라
A8: 4 | B8: 12/7 | C8: 월 | D8: 하코네·후지 | E8: 하코네 (아시노호수) | F8: 2박 | G8: 걷기 | H8: =IF('이동 상세'!H9="","",HYPERLINK('경로 좌표'!N7,'이동 상세'!H9)) -> 16.9 | I8: =IF('이동 상세'!H9="","",'이동 상세'!I9) -> 0.17604167 | J8: =IF('이동 상세'!P9="","",'이동 상세'!P9) -> 0.33333333 | K8: =IF('이동 상세'!Q9="","",'이동 상세'!Q9) -> 0.571875 | L8: =IF('이동 상세'!S9="","",'이동 상세'!S9) -> 0.116685 | M8: 산길 오르막 | N8: 10 하코네 | O8: 걷기)오다와라 → 하코네 옛 돌길 → 아마자케차야 → 하코네 관소 | Q8: 4 | R8: 12/7 | S8: 하코네·후지 | T8: 하코네 (아시노호수) | U8: 하코네 옛 돌길, 아마자케차야, 삼나무 가로수길, 하코네 관소, 하코네 신사 (호숫가 도리이) 온천: 하코네유모토 온천 (당일 입욕 시설이 많음), 아시노호수 쪽 숙소 온천 | V8: 하코네유모토: 온천 만주 아마자케차야 (돌길 중간): 아마자케, 지카라모치 떡 | W8: 하타주쿠 (돌길 입구 마을): 하코네 요세기자이쿠 (나무 쪽매붙임 공예) | X8: 돌길은 1680년 무렵 진흙길에 돌을 깔아 만든 길. 하코네 관소는 에도로 들어오는 무기와 빠져나가는 다이묘 부인을 감시했습니다. | Y8: 도쿄 사람들이 주말에 찾는 대표 온천 휴양지. 매년 1월 2~3일에는 대학생들이 도쿄~하코네를 왕복하는 역전 마라톤 '하코네 에키덴'이 이 길을 달리는데, 일본 새해 최고 인기 중계입니다. | Z8: 산길: +1시간, 결빙·폭설 시 플랜 B: 하코네 토잔 버스 비올때: 하코네 토잔 버스 (하코네유모토역 ↔ 하타주쿠·아마자케차야 ↔ 하코네마치)
A9: 5 | B9: 12/8 | C9: 화 | D9: 하코네·후지 | E9: 하코네 (아시노호수) | F9: ↑ | G9: 휴식 | H9: =IF('이동 상세'!H10="","",'이동 상세'!H10) | I9: =IF('이동 상세'!H10="","",'이동 상세'!I10) | J9: =IF('이동 상세'!P10="","",'이동 상세'!P10) | K9: =IF('이동 상세'!Q10="","",'이동 상세'!Q10) | L9: =IF('이동 상세'!S10="","",'이동 상세'!S10) | M9: 하코네 온천 휴식 | O9: 관광)아시노호수 유람선·온시하코네 공원·숙소 온천 | Q9: 5 | R9: 12/8 | S9: 하코네·후지 | T9: 하코네 (아시노호수) | U9: 아시노호수 유람선 (맑으면 호수 너머 후지산), 온시하코네 공원 (옛 황실 별궁 터, 호수 전망) 온천: 숙소 온천에서 푹 쉬기 · 기운이 남으면 하코네유모토 온천 당일 입욕 (버스 약 40분) | V9: 하코네마치·모토하코네: 아시노호수 빙어(와카사기) 튀김, 송어 요리 오와쿠다니 (선택, 로프웨이): 구로타마고 (검은 달걀) | W9: 하코네: 요세기자이쿠 (나무 쪽매붙임 공예) 구로타마고 (오와쿠다니 검은 달걀) | X9: 아시노호수는 약 3,000년 전 하코네 화산 활동으로 생긴 호수입니다. 온시하코네 공원은 메이지 시대 황실 별궁(하코네 이궁)이 있던 자리입니다. | Y9: 하코네 고개를 넘기 전, 산길 이틀 사이에 하루 쉬며 발과 다리를 회복하는 날입니다. 날씨가 나쁘면 이날을 예비일로 써서 하루 늦게 고개를 넘습니다. | Z9: 결빙·폭설 예보가 있으면 이날을 예비일로 써서 하루 늦게 고개를 넘어도 됨
A10: 6 | B10: 12/9 | C10: 수 | D10: 하코네·후지 | E10: 미시마 | F10: 1박 | G10: 걷기 | H10: =IF('이동 상세'!H11="","",HYPERLINK('경로 좌표'!N8,'이동 상세'!H11)) -> 18.4 | I10: =IF('이동 상세'!H11="","",'이동 상세'!I11) -> 0.19166667 | J10: =IF('이동 상세'!P11="","",'이동 상세'!P11) -> 0.33333333 | K10: =IF('이동 상세'!Q11="","",'이동 상세'!Q11) -> 0.5875 | L10: =IF('이동 상세'!S11="","",'이동 상세'!S11) -> 0.10165 | M10: 산길 내리막 | N10: 11 미시마 | O10: 걷기)하코네 관소 → 하코네 고개 → 야마나카성터 → 미시마 다이샤 | Q10: 6 | R10: 12/9 | S10: 하코네·후지 | T10: 미시마 | U10: 하코네 고개 (맑으면 후지산), 야마나카성터 (와플 모양 해자) 미시마 다이샤, 겐베가와 맑은 물 산책로 온천: 숙소 대욕장 (도미 인 미시마는 천연 온천) | V10: 미시마역 주변 (미시마 다이샤 근처): 장어 덮밥 (후지산 용천수로 손질) 미시마 고로케 | W10: 미시마 다이샤: '후쿠타로' 떡 미시마: 미시마 채소 (하코네 서쪽 산비탈 밭) | X10: 야마나카성은 호조 가문이 히데요시군을 막으려 쌓은 산성으로 1590년 하루 만에 함락. 미시마 다이샤는 미나모토노 요리토모가 거병 전 승리를 빈 신사입니다. | Y10: 후지산 눈 녹은 물이 시내 곳곳에서 솟는 '물의 도시'. 신칸센으로 도쿄까지 약 45분이라 도쿄로 출퇴근하는 사람도 삽니다. | Z10: 산길: +1간, 하코네 체크아웃 결빙·폭설 시 플랜 B: 버스로 미시마까지 비올때: 도카이 버스 (하코네 고개·야마나카성터 정류장 → 미시마역)
A11: 7 | B11: 12/10 | C11: 목 | D11: 하코네·후지 | E11: 후지 요시와라 | F11: 1박 | G11: 걷기 | H11: =IF('이동 상세'!H12="","",HYPERLINK('경로 좌표'!N9,'이동 상세'!H12)) -> 26.3 | I11: =IF('이동 상세'!H12="","",'이동 상세'!I12) -> 0.27395833 | J11: =IF('이동 상세'!P12="","",'이동 상세'!P12) -> 0.29166667 | K11: =IF('이동 상세'!Q12="","",'이동 상세'!Q12) -> 0.60729167 | L11: =IF('이동 상세'!S12="","",'이동 상세'!S12) -> 0.082518333 | M11: 해안 소나무길 (가장 긴 날) | N11: 12 누마즈 13 하라 14 요시와라 | O11: 걷기)미시마 → 누마즈 → 센본마쓰바라 → 하라 → 요시와라 | Q11: 7 | R11: 12/10 | S11: 하코네·후지 | T11: 후지 요시와라 | U11: 센본마쓰바라 소나무 해변, 누마즈항, 요시와라 상점가 (저녁 숙소 마을) 온천: 숙소 대욕장 (요시와라 일부 호텔은 작은 온천) | V11: 누마즈항 (걷는 길에서 2km 벗어남): 해산물 덮밥, 전갱이 튀김·회 요시와라 상점가 (저녁, 숙소 마을): 후지 쓰케나폴리탄 (나폴리탄 스파게티) | W11: 누마즈항: 전갱이 건어물 (누마즈가 일본 최대 산지) | X11: 센본마쓰바라는 바닷바람을 막으려고 심은 소나무 숲. 하라는 일본 임제종을 다시 일으킨 선승 하쿠인의 고향입니다. | Y11: 스루가만의 어항 도시 누마즈를 지나 제지 공업 도시 후지시 요시와라까지 걷습니다. 누마즈는 애니메이션 「러브라이브! 선샤인!!」의 무대라 팬들의 '성지순례' 방문객이 많습니다. | Z11: 미시마 체크아웃 비올때:JR 도카이도선 누마즈·가타하마·하라·히가시타고노우라·요시와라역
A12: 8 | B12: 12/11 | C12: 금 | D12: 하코네·후지 | E12: 오키쓰 | F12: 2박 | G12: 걷기 | H12: =IF('이동 상세'!H13="","",HYPERLINK('경로 좌표'!N10,'이동 상세'!H13)) -> 21.5 | I12: =IF('이동 상세'!H13="","",'이동 상세'!I13) -> 0.22395833 | J12: =IF('이동 상세'!P13="","",'이동 상세'!P13) -> 0.33333333 | K12: =IF('이동 상세'!Q13="","",'이동 상세'!Q13) -> 0.61979167 | L12: =IF('이동 상세'!S13="","",'이동 상세'!S13) -> 0.070718333 | M12: 후지강·유이·삿타 고개 | N12: 15 간바라 16 유이 17 오키쓰 | O12: 걷기)요시와라 → 후지강 다리 → 간바라 → 유이 (점심) → 삿타 고개 → 오키쓰 | Q12: 8 | R12: 12/11 | S12: 하코네·후지 | T12: 오키쓰 | U12: 히다리 후지 신사 (도카이도에서 유일하게 후지산이 왼쪽에 보이는 곳) 후지강 다리 (후지산 전망), 유이 옛 거리, 삿타 고개 (후지산과 스루가만) | V12: 유이 (점심, 유이역·유이항 주변): 사쿠라에비 (벚꽃새우) 튀김·덮밥 시라스 (잔멸치) 덮밥 오키쓰 (저녁): 숙소 식당 (쿠어 앤 호텔 스루가) | W12: 후지시: 종이 (화장지 등 종이 생산으로 손꼽히는 제지 도시) 유이: 사쿠라에비 (일본에서는 스루가만에서만 잡힘, 가을 어기가 12월까지) | X12: 요시와라주쿠는 쓰나미로 두 번 자리를 옮겼고, 그 때문에 길이 굽어 이곳에서만 후지산이 왼쪽에 보입니다. 삿타 고개는 히로시게의 그림 「도카이도 53역참」 속 풍경이 거의 그대로 남은 곳 | Y12: 제지 공장 굴뚝과 후지산을 보며 후지강을 건너 작은 어촌 유이를 지나고, 삿타 고개에서 후지산과 바다를 함께 본 뒤 오키쓰 온천 숙소로 내려갑니다. | Z12: 요시와라 체크아웃 힘들 때·비 올 때: JR 도카이도선 후지·후지카와·신칸바라·유이·오키쓰역 (삿타 고개는 비 오면 미끄러우니 유이→오키쓰는 기차로)
A13: 9 | B13: 12/12 | C13: 토 | D13: 시즈오카 | E13: 오키쓰 | F13: ↑ | G13: 휴식 | H13: =IF('이동 상세'!H14="","",'이동 상세'!H14) | I13: =IF('이동 상세'!H14="","",'이동 상세'!I14) | J13: =IF('이동 상세'!P14="","",'이동 상세'!P14) | K13: =IF('이동 상세'!Q14="","",'이동 상세'!Q14) | L13: =IF('이동 상세'!S14="","",'이동 상세'!S14) | M13: 오키쓰 온천 휴식 | O13: 관광)세이켄지·오키쓰 옛 거리 (걸어서), 관광)미호노마쓰바라 (선택, 버스), 관광)숙소 온천에서 쉬기 | Q13: 9 | R13: 12/12 | S13: 시즈오카 | T13: 오키쓰 | U13: 세이켄지 (조선통신사 유적, 08:30~16:00, 숙소에서 약 1km), 오키쓰 옛 거리 미호노마쓰바라 (선택, 버스) 온천: 숙소 온천·스파 (쿠어 앤 호텔 스루가) | V13: 오키쓰: 식당이 적어 숙소 식당이 편함 미호 (선택): 해변 찻집 | W13: 오키쓰: 오키쓰다이 (옥돔 건어물) | X13: 오키쓰의 세이켄지는 조선통신사가 묵거나 들르던 절로, 통신사가 쓴 편액 7점이 남아 '조선통신사 유적'으로 국가 사적에 지정. 미호노마쓰바라는 후지산 세계문화유산의 구성 자산으로 등재된 소나무 해변 | Y13: 오키쓰는 메이지·다이쇼 시대 정치인들의 별장지였던 조용한 바닷가 마을입니다. 약 66km를 걸은 뒤 온천에서 쉬며, 세이켄지에서 조선통신사의 흔적을 천천히 봅니다. | Z13: 약 66km를 걸은 뒤 쉬는 날 (온천).
A14: 10 | B14: 12/13 | C14: 일 | D14: 시즈오카 | E14: 시즈오카 | F14: 1박 | G14: 걷기 | H14: =IF('이동 상세'!H15="","",HYPERLINK('경로 좌표'!N11,'이동 상세'!H15)) -> 19.1 | I14: =IF('이동 상세'!H15="","",'이동 상세'!I15) -> 0.19895833 | J14: =IF('이동 상세'!P15="","",'이동 상세'!P15) -> 0.35416667 | K14: =IF('이동 상세'!Q15="","",'이동 상세'!Q15) -> 0.59479167 | L14: =IF('이동 상세'!S15="","",'이동 상세'!S15) -> 0.096558333 | M14: 에지리·구사나기 | N14: 18 에지리 19 후추 (시즈오카) | O14: 걷기)오키쓰 → 에지리 (시미즈, 가시노이치 점심) → 구사나기 → 시즈오카 | Q14: 10 | R14: 12/13 | S14: 시즈오카 | T14: 시즈오카 | U14: 에지리 (시미즈) 옛 거리, 구사나기 일리총 (옛 도카이도), 구사나기 신사 (옛길에서 남쪽으로 약 1km), 슨푸성 공원 (도착 후) | V14: 시미즈 (점심): 시미즈항 가시노이치 참치 덮밥 (옛길에서 약 1km) 시즈오카역 주변 (저녁): 시즈오카 오뎅 (검은 국물) | W14: 시즈오카: 녹차, 프라모델 (일본 프라모델 대부분을 생산) | X14: 구사나기는 야마토타케루가 들판에서 불길에 갇히자 칼로 풀을 베어 빠져나왔다는 전설에서 이름이 왔고, 그 칼이 아쓰타 신궁에 모신 구사나기 검입니다. 도쿠가와 이에야스가 말년을 보낸 슨푸가 지금의 시즈오카입니다. | Y14: 시즈오카현의 현청 소재지. 녹차 거래의 중심이고, 타미야·반다이 공장이 있는 '프라모델의 수도'로 불립니다. | Z14: 오키쓰 체크아웃 힘들 때·비 올 때: JR 도카이도선 오키쓰·시미즈·구사나기·히가시시즈오카·시즈오카역
A15: 11 | B15: 12/14 | C15: 월 | D15: 시즈오카 | E15: 후지에다 | F15: 1박 | G15: 걷기 | H15: =IF('이동 상세'!H16="","",HYPERLINK('경로 좌표'!N12,'이동 상세'!H16)) -> 23.2 | I15: =IF('이동 상세'!H16="","",'이동 상세'!I16) -> 0.24166667 | J15: =IF('이동 상세'!P16="","",'이동 상세'!P16) -> 0.3125 | K15: =IF('이동 상세'!Q16="","",'이동 상세'!Q16) -> 0.61666667 | L15: =IF('이동 상세'!S16="","",'이동 상세'!S16) -> 0.075443333 | M15: 마리코·우쓰노야 고개 | N15: 20 마리코 21 오카베 22 후지에다 | O15: 걷기)시즈오카 → 마리코 (조지야 점심) → 우쓰노야 고개 → 오카베 → 후지에다 | Q15: 11 | R15: 12/14 | S15: 시즈오카 | T15: 후지에다 | U15: 마리코 조지야 (1596년 창업, 히로시게 그림 속 가게, 점심), 우쓰노야 옛 고갯길, 오카베주쿠 옛 거리 | V15: 마리코 조지야 (점심, 월요일은 11:00~14:00 무렵): 도로로지루 (참마즙 정식) 오카베: 아사히나 교쿠로 (일본 3대 교쿠로 산지의 고급 녹차) 찻집 후지에다 시내 (저녁): 식당가 | W15: 우쓰노야 고개 마을: '주단고' (작은 경단을 꿴 액막이) | X15: 마리코의 도로로지루는 바쇼의 하이쿠에도 나오는 명물입니다. 우쓰노야 고개의 '쓰타노호소미치'(담쟁이 오솔길)는 헤이안 시대 『이세 이야기』에 나오는 옛길입니다. | Y15: 시즈오카 시내에서 조금만 벗어나면 차밭과 산이 이어지는 조용한 산골. 고개를 넘어 오카베를 지나면 축구의 도시 후지에다입니다. | Z15: 시즈오카 체크아웃 힘들 때·비 올 때: 시즈테쓰 버스 (시즈오카역 → 마리코, 국도 1호선 우쓰노야 입구·오카베 정류장 → 후지에다)
A16: 12 | B16: 12/15 | C16: 화 | D16: 시즈오카 | E16: 시마다 | F16: 1박 | G16: 걷기 | H16: =IF('이동 상세'!H17="","",HYPERLINK('경로 좌표'!N13,'이동 상세'!H17)) -> 7.8 | I16: =IF('이동 상세'!H17="","",'이동 상세'!I17) -> 0.08125 | J16: =IF('이동 상세'!P17="","",'이동 상세'!P17) -> 0.4375 | K16: =IF('이동 상세'!Q17="","",'이동 상세'!Q17) -> 0.56041667 | L16: =IF('이동 상세'!S17="","",'이동 상세'!S17) -> 0.13213333 | M16: 평지 짧은 날, 회복 | N16: 23 시마다 | O16: 걷기)후지에다 → 시마다역 | Q16: 12 | R16: 12/15 | S16: 시즈오카 | T16: 시마다 | U16: 시마다 오이가와 가와고시 유적 (강 건너기 대기소 거리) | V16: 후지에다 시내: 아침 라멘 (아침부터 라멘을 먹는 지역 문화) | X16: 에도 막부는 방어를 위해 오이가와에 다리를 놓지 않아, 여행자는 인부의 어깨나 가마에 실려 강을 건넜습니다. | Y16: 후지에다는 고교 축구 명문교가 모여 '축구의 도시'로 불립니다. 시마다 옆 오이가와 철도에서는 지금도 증기기관차가 달립니다. | Z16: 후지에다 체크아웃 짧은 날: 늦잠 자고 출발. 힘들 때·비 올 때: JR 도카이도선 후지에다·롯고·시마다역
A17: 13 | B17: 12/16 | C17: 수 | D17: 시즈오카 | E17: 가케가와 | F17: 1박 | G17: 걷기 | H17: =IF('이동 상세'!H18="","",HYPERLINK('경로 좌표'!N14,'이동 상세'!H18)) -> 22.6 | I17: =IF('이동 상세'!H18="","",'이동 상세'!I18) -> 0.23541667 | J17: =IF('이동 상세'!P18="","",'이동 상세'!P18) -> 0.3125 | K17: =IF('이동 상세'!Q18="","",'이동 상세'!Q18) -> 0.61041667 | L17: =IF('이동 상세'!S18="","",'이동 상세'!S18) -> 0.082903333 | M17: 돌길·차밭, 긴 날 | N17: 24 가나야 25 닛사카 26 가케가와 | O17: 걷기)시마다 → 호라이교 → 가나야 돌길 → 닛사카 → 가케가와역 관광)가케가와성 (도착 후) | Q17: 13 | R17: 12/16 | S17: 시즈오카 | T17: 가케가와 | U17: 호라이교 (세계에서 가장 긴 목조 보도교, 897m) 가나야 돌길, 마키노하라 차밭, 요나키이시 (밤에 우는 돌) 가케가와성 (도착 후, 목조 복원 천수각·니노마루 고텐) | V17: 가나야 돌길 위 찻집: 녹차 닛사카 (사요노나카야마 고개 찻집): 고소다테 아메 (물엿) | W17: 마키노하라: 녹차 (일본 최대 차 산지) 닛사카: 고소다테 아메 가케가와: 구즈후 (칡 섬유로 짠 전통 직물) | X17: 요나키이시 전설: 산적에게 죽은 임신부의 혼이 돌에 깃들어 밤마다 울었고, 태어난 아기를 스님이 물엿으로 키웠다는 이야기. 그 물엿이 고소다테 아메입니다. | Y17: 끝없이 펼쳐진 차밭 지대. 근처에 시즈오카공항이 있고, 가케가와는 신칸센이 서는 차 산업 도시입니다. | Z17: 시마다 체크아웃 비 올 때: JR 가나야역 (가나야 돌길 전), 닛사카에서는 가케가와역행 버스
A18: 14 | B18: 12/17 | C18: 목 | D18: 엔슈 | E18: 하마나호 (와시즈) | F18: 2박 | G18: 교통+걷기 | H18: =IF('이동 상세'!H19="","",HYPERLINK('경로 좌표'!N15,'이동 상세'!H19)) -> 20.8 | I18: =IF('이동 상세'!H19="","",'이동 상세'!I19) -> 0.21666667 | J18: =IF('이동 상세'!P19="","",'이동 상세'!P19) -> 0.33333333 | K18: =IF('이동 상세'!Q19="","",'이동 상세'!Q19) -> 0.59166667 | L18: =IF('이동 상세'!S19="","",'이동 상세'!S19) -> 0.10331333 | M18: 하마나호 | N18: 29 하마마쓰 30 마이사카 31 아라이 | O18: 교통)가케가와역 → 하마마쓰역 (JR, 약 30분) 걷기)하마마쓰 → 마이사카 → 벤텐지마 → 아라이 관소 → 와시즈 (호숫가 숙소) | Q18: 14 | R18: 12/17 | S18: 엔슈 | T18: 하마나호 (와시즈) | U18: 마이사카 소나무 가로수길, 벤텐지마 (하마나호의 붉은 도리이) 아라이 관소 (건물이 남은 유일한 관소), 하마나호 호숫가 숙소 (저녁 노을) | V18: 벤텐지마·아라이 (점심): 장어, 굴 (겨울이 제철) 와시즈 (저녁): 숙소 주변 식당 | W18: 하마나호: 장어·굴 양식 | X18: 하마나호는 원래 민물 호수였는데, 1498년 큰 지진과 해일로 바다와 이어져 지금 같은 바닷물 호수가 되었습니다. 아라이 관소는 하코네와 함께 도카이도의 2대 관소로, 하마나호를 배로 건너온 여행자를 검문했습니다. | Y18: 아라이가 속한 고사이시는 도요타 그룹 창업자 도요다 사키치의 고향입니다. 하마나호는 장어와 굴 양식으로 유명합니다. | Z18: 교통 이유: 가케가와~하마마쓰 약 28km는 국도 1호선 옆 평탄한 시가지와 공장 지대라 볼거리가 적음, 비 올 때: JR 도카이도선 다카쓰카·마이사카·벤텐지마·아라이마치·와시즈역
A19: 15 | B19: 12/18 | C19: 금 | D19: 엔슈 | E19: 하마나호 (와시즈) | F19: ↑ | G19: 휴식 | H19: =IF('이동 상세'!H20="","",'이동 상세'!H20) | I19: =IF('이동 상세'!H20="","",'이동 상세'!I20) | J19: =IF('이동 상세'!P20="","",'이동 상세'!P20) | K19: =IF('이동 상세'!Q20="","",'이동 상세'!Q20) | L19: =IF('이동 상세'!S20="","",'이동 상세'!S20) | M19: 하마나호 쉬는 날 | O19: 관광)숙소에서 늦잠, 교통)와시즈역 → 하마마쓰역 (JR) → 간잔지 온천 (버스) 관광)간잔지 온천·유람선·장어 (원하는 곳만) | Q19: 15 | R19: 12/18 | S19: 엔슈 | T19: 하마나호 (와시즈) | U19: 간잔지 온천 (호숫가 온천 마을, 당일 입욕), 하마나호 유람선 등 가는 길: 와시즈역 → JR 하마마쓰역 (약 20분) → 버스 간잔지 온천 (약 50분) | V19: 간잔지·하마마쓰: 장어 덮밥, 하마마쓰 교자 | W19: 하마마쓰: 피아노·악기 (야마하·가와이 본사) 오토바이 (스즈키·야마하·혼다가 시작된 곳) | X19: 하마마쓰성은 이에야스가 29세부터 17년간 머물며 세력을 키운 '출세의 성'입니다. 간잔지는 8세기 고승 교키가 열었다고 전하는 절로, 호숫가 온천 마을의 이름이 되었습니다. | Y19: 약 93km를 걸은 뒤 호숫가에서 쉬는 날. 하마나호는 둘레 약 114km의 바닷물 호수로 장어·굴 양식과 저녁 노을로 유명합니다. | Z19: 약 93km를 걸은 뒤 쉬는 날 (호숫가).
A20: 16 | B20: 12/19 | C20: 토 | D20: 미카와 | E20: 도요하시 | F20: 2박 | G20: 걷기 | H20: =IF('이동 상세'!H21="","",HYPERLINK('경로 좌표'!N16,'이동 상세'!H21)) -> 23 | I20: =IF('이동 상세'!H21="","",'이동 상세'!I21) -> 0.23958333 | J20: =IF('이동 상세'!P21="","",'이동 상세'!P21) -> 0.3125 | K20: =IF('이동 상세'!Q21="","",'이동 상세'!Q21) -> 0.59375 | L20: =IF('이동 상세'!S21="","",'이동 상세'!S21) -> 0.10213 | M20: 바다 전망, 긴 날 | N20: 32 시라스카 33 후타가와 34 요시다 (도요하시) | O20: 걷기)와시즈 → 시라스카 → 시오미자카 → 후타가와 본진 → 도요하시 | Q20: 16 | R20: 12/19 | S20: 미카와 | T20: 도요하시 | U20: 시오미자카 (서쪽으로 가던 여행자가 처음 태평양을 보던 언덕), 후타가와주쿠 본진 자료관 | V20: 도요하시역 주변: 도요하시 카레우동 (아래에 밥과 참마즙이 깔린 우동) | W20: 도요하시: 붓 (국가 전통공예품), 지쿠와 (어묵) | X20: 후타가와주쿠는 다이묘가 묵던 본진 건물이 남은 도카이도의 두 역참 가운데 하나입니다(다른 하나는 구사쓰). | Y20: 아이치현 동부의 중심 도시. 노면전차가 다니고, 가까운 미카와항은 일본에서 수입차를 가장 많이 들여오는 항구입니다. | Z20: 하마나호 체크아웃 도요하시 숙소 두 곳(어소시아·도미 인)이 모두 표시돼 있으니 하나로 정하기. 힘들 때·비 올 때: JR 도카이도선 와시즈·신조하라·후타가와역
A21: 17 | B21: 12/20 | C21: 일 | D21: 미카와 | E21: 도요하시 | F21: ↑ | G21: 걷기+교통 | H21: =IF('이동 상세'!H22="","",HYPERLINK('경로 좌표'!N17,'이동 상세'!H22)) -> 13.7 | I21: =IF('이동 상세'!H22="","",'이동 상세'!I22) -> 0.14270833 | J21: =IF('이동 상세'!P22="","",'이동 상세'!P22) -> 0.39583333 | K21: =IF('이동 상세'!Q22="","",'이동 상세'!Q22) -> 0.58020833 | L21: =IF('이동 상세'!S22="","",'이동 상세'!S22) -> 0.11600167 | M21: 소나무 가로수길 | N21: 35 고유 36 아카사카 | O21: 걷기)도요하시 → 고유 소나무 가로수길 → 아카사카 교통)메이덴아카사카역 → 도요하시역 (메이테쓰) | Q21: 17 | R21: 12/20 | S21: 미카와 | T21: 도요하시 | U21: 고유 소나무 가로수길 (국가 천연기념물, 약 600m), 아카사카 오하시야 (에도 시대 여관 건물) | V21: 도요카와 이나리 주변 (걷는 길에서 버스·전철로 약 15분) : 이나리즈시 (유부초밥) | X21: 고유와 아카사카는 1.7km밖에 떨어지지 않은 역참이라 호객 경쟁이 치열했습니다. 오하시야는 히로시게 그림 「아카사카」의 무대로 알려진 여관입니다. | Y21: 도요카와시의 조용한 주거지. 일본 3대 이나리 신사로 꼽히는 도요카와 이나리가 가까워 새해 참배객이 많이 찾습니다. | Z21: 교통 이유: 아카사카는 숙소가 적어, 연박하는 도요하시 숙소로 돌아감. 힘들 때·비 올 때: 메이테쓰 고우·고유·메이덴아카사카역
A22: 18 | B22: 12/21 | C22: 월 | D22: 미카와 | E22: 오카자키 | F22: 1박 | G22: 교통+걷기 | H22: =IF('이동 상세'!H23="","",HYPERLINK('경로 좌표'!N18,'이동 상세'!H23)) -> 19.9 | I22: =IF('이동 상세'!H23="","",'이동 상세'!I23) -> 0.20729167 | J22: =IF('이동 상세'!P23="","",'이동 상세'!P23) -> 0.35416667 | K22: =IF('이동 상세'!Q23="","",'이동 상세'!Q23) -> 0.603125 | L22: =IF('이동 상세'!S23="","",'이동 상세'!S23) -> 0.093615 | M22: 평지 | N22: 37 후지카와 38 오카자키 | O22: 교통)도요하시역 → 메이덴아카사카역 (메이테쓰) 걷기)아카사카 → 후지카와 → 오카자키성 → 히가시오카자키 (숙소) 관광)오카자키성·핫초 미소 공장 | Q22: 18 | R22: 12/21 | S22: 미카와 | T22: 오카자키 | U22: 오카자키성, 핫초 미소 공장 견학 (가쿠큐·마루야, 도착 후 오후) | V22: 오카자키성 주변: 핫초 미소 니코미 우동 | W22: 오카자키: 핫초 미소 (콩 된장), 석제품 (돌 등롱 등, 국가 전통공예품) | X22: 도쿠가와 이에야스가 태어난 곳. 성에서 서쪽으로 핫초(약 870m) 떨어진 마을에서 만들어 핫초 미소라 부릅니다. 핫초 미소 공장 두 곳은 에도 시대부터 같은 자리에서 나무통에 2년 넘게 숙성하는 방식을 지키고 있습니다. | Y22: 도요타 자동차 관련 산업이 받치는 인구 38만의 도시. 2023년 NHK 대하드라마 「어떻게 할래 이에야스」의 무대였습니다. | Z22: 교통 이유: 도요하시 숙소에서 출발점(아카사카)으로 이동. 힘들 때·비 올 때: 메이테쓰 메이덴나가사와·모토주쿠·후지카와·히가시오카자키역
A23: 19 | B23: 12/22 | C23: 화 | D23: 나고야 | E23: 나고야 | F23: 1박 | G23: 교통+걷기+교통 | H23: =IF('이동 상세'!H24="","",HYPERLINK('경로 좌표'!N19,'이동 상세'!H24)) -> 19.8 | I23: =IF('이동 상세'!H24="","",'이동 상세'!I24) -> 0.20625 | J23: =IF('이동 상세'!P24="","",'이동 상세'!P24) -> 0.35416667 | K23: =IF('이동 상세'!Q24="","",'이동 상세'!Q24) -> 0.60208333 | L23: =IF('이동 상세'!S24="","",'이동 상세'!S24) -> 0.095416667 | M23: 아리마쓰 옛 거리 | N23: 39 지류 40 나루미 41 미야 (아쓰타) | O23: 교통)히가시오카자키역 → 지류역 (메이테쓰), 걷기)지류 → 아리마쓰 옛 거리 → 나루미 → 아쓰타 신궁 교통)진구마에역 → 나고야역 (메이테쓰) | Q23: 19 | R23: 12/22 | S23: 나고야 | T23: 나고야 | U23: 아리마쓰 옛 거리 (전통 건축물 보존지구), 오케하자마 전투지, 아쓰타 신궁 | V23: 아쓰타 신궁 근처 (아쓰타 호라이켄 본점): 히쓰마부시 (1873년 창업, 장어덮밥) 아쓰타 신궁 경내: 기시멘 (넓적한 우동) | W23: 아리마쓰: 시보리 (홀치기염색 천, 국가 전통공예품) | X23: 1560년 오케하자마 전투에서 오다 노부나가가 대군의 이마가와 요시모토를 기습해 이겼습니다. 아쓰타 신궁은 3종 신기 중 하나인 구사나기 검을 모신 곳입니다. 아리마쓰 옛거리는 나고야 근교에 위치한 전통 쪽빛 염색(아리마쓰 시보리)으로 유명한 옛 거리입니다. 검은 벽과 독특한 처마를 가진 옛 상가 건물이 길게 이어져 있어 걷는 재미가 쏠쏠합니다. | Y23: 나고야는 도쿄·오사카와 함께 일본 3대 도시. 도요타를 중심으로 한 제조업의 심장부이고, 2026년 아시안게임 개최 도시입니다. | Z23: 교통 이유: 아침: 오카자키~지류 약 15km는 국도 1호선과 공장 지대 사이라 볼거리가 적어 전철로 건너뜀. 저녁: 아쓰타 신궁에서 나고야역 숙소로. 힘들 때·비 올 때: 메이테쓰 아리마쓰·나루미역 등에서 진구마에역
A24: 20 | B24: 12/23 | C24: 수 | D24: 나고야 | E24: 구와나 | F24: 1박 | G24: 휴식 | H24: =IF('이동 상세'!H25="","",'이동 상세'!H25) | I24: =IF('이동 상세'!H25="","",'이동 상세'!I25) | J24: =IF('이동 상세'!P25="","",'이동 상세'!P25) | K24: =IF('이동 상세'!Q25="","",'이동 상세'!Q25) | L24: =IF('이동 상세'!S25="","",'이동 상세'!S25) | M24: 이동하며 쉬는 날 | N24: 42 구와나 (숙박) | O24: 관광)나고야성 (오전), 교통)나고야역 → 구와나역 (JR·긴테쓰) 관광)대합 점심·나가시마 온천·나바나노사토 (원하는 곳만) | Q24: 20 | R24: 12/23 | S24: 나고야 | T24: 구와나 | U24: 오전: 나고야성 (혼마루 궁전) → 구와나로 이동, 구와나 시치리노와타시 터 나바나노사토 겨울 일루미네이션 (밤, 구와나 숙소로 돌아오기 쉬움) 온천: 나가시마 온천 '유아미노시마' (구와나역에서 버스) | V24: 구와나 (점심): 대합구이·대합 샤부샤부 나고야 (저녁): 미소카쓰, 데바사키 (닭날개 튀김) | W24: 구와나: 대합 시구레니 (조림) · 나고야: 우이로 (쌀 떡과자) | X24: 에도 시대에는 아쓰타에서 구와나까지 바다로 7리(약 28km)를 배로 건넜습니다. 그래서 이 구간은 걷는 길이 없습니다. 나고야성은 1612년 무렵 이에야스의 명으로 지은 성으로, 지붕 위 금 샤치호코로 유명합니다. | Y24: 나고야의 베드타운. 나가시마 스파랜드(놀이공원), 아웃렛, 온천, 나바나노사토가 모인 나가시마 리조트로 주말 나들이객이 몰립니다. | Z24: 나고야 체크아웃 크리스마스 이브. 오전에 나고야성, 오후부터 구와나에서 쉬기. 가고 싶은 곳만 고르세요.
A25: 21 | B25: 12/24 | C25: 목 | D25: 스즈카 | E25: 가메야마 (세키 입구) | F25: 1박 | G25: 교통+걷기 | H25: =IF('이동 상세'!H26="","",HYPERLINK('경로 좌표'!N20,'이동 상세'!H26)) -> 13.7 | I25: =IF('이동 상세'!H26="","",'이동 상세'!I26) -> 0.14270833 | J25: =IF('이동 상세'!P26="","",'이동 상세'!P26) -> 0.39583333 | K25: =IF('이동 상세'!Q26="","",'이동 상세'!Q26) -> 0.58020833 | L25: =IF('이동 상세'!S26="","",'이동 상세'!S26) -> 0.11989167 | M25: 쇼노·가메야마 | N25: 45 쇼노 46 가메야마 | O25: 교통)구와나역 → 가사도역 (JR 간사이본선) 걷기)가사도 → 쇼노 → 가메야마 → 세키 입구 (칸데오 호텔) | Q25: 21 | R25: 12/24 | S25: 스즈카 | T25: 가메야마 (세키 입구) | U25: 세키주쿠 옛 거리 (옛 역참 거리가 1.8km 이어진 전통 건축물 보존지구), 세키 지조인 | V25: 가메야마역 주변: 미소야키우동 · 세키주쿠 옛 거리: 세키노토 (화과자) | W25: 세키주쿠: 세키노토 (1600년대부터 이어진 화과자) 가메야마: 양초 (일본 대표 양초 브랜드의 고장) | X25: 세키주쿠는 도카이도 역참 가운데 옛 모습이 가장 잘 남은 곳으로, 에도 말기~메이지 시대 건물 200여 채가 늘어서 있습니다. | Y25: 가메야마는 샤프의 LCD TV 공장으로 유명해져 한때 '가메야마 모델'이 TV의 고급 상표처럼 쓰였습니다. | Z25: 세키 입구의 칸데오 호텔에서 묵고, 다음 날 아침 세키주쿠 옛 거리를 지나 스즈카 고개로 갑니다. 세키주쿠 옛 거리는 다음 날 아침 숙소에서 걸어서 지나갑니다. 힘들 때·비 올 때: JR 간사이본선 가메야마·세키역
A26: 22 | B26: 12/25 | C26: 금 | D26: 오미 | E26: 미나쿠치 | F26: 1박 | G26: 걷기+교통 | H26: =IF('이동 상세'!H27="","",HYPERLINK('경로 좌표'!N21,'이동 상세'!H27)) -> 18.1 | I26: =IF('이동 상세'!H27="","",'이동 상세'!I27) -> 0.18854167 | J26: =IF('이동 상세'!P27="","",'이동 상세'!P27) -> 0.33333333 | K26: =IF('이동 상세'!Q27="","",'이동 상세'!Q27) -> 0.584375 | L26: =IF('이동 상세'!S27="","",'이동 상세'!S27) -> 0.116335 | M26: 스즈카 고개 (산길) | N26: 47 세키 48 사카시타 49 쓰치야마 50 미나쿠치 | O26: 걷기)숙소 → 세키주쿠 옛 거리 → 사카시타 → 스즈카 고개 → 쓰치야마 교통)쓰치야마 → 기부카와역 (버스) → 미나쿠치 (오미철도) | Q26: 22 | R26: 12/25 | S26: 오미 | T26: 미나쿠치 | U26: 세키주쿠 옛 거리 (아침, 에도 시대 상가가 약 1.8km 이어지는 중요 전통 건조물군 보존지구), 스즈카 고개, 가가미이와 (거울 바위), 쓰치야마 차밭 | V26: 쓰치야마 (도로 휴게소 아이노 쓰치야마): 쓰치야마 녹차 | W26: 쓰치야마: 쓰치야마차 (오미차) | X26: 하코네와 함께 도카이도의 2대 난소. 산적이 많기로 유명했고, 가가미이와는 산적이 여행자를 비춰 봤다는 전설의 바위입니다. | Y26: 고개 너머는 시가현 고카시의 차밭 지대. 고개 동쪽 스즈카시는 F1 일본 그랑프리가 열리는 스즈카 서킷이 있는 곳입니다. | Z26: 산길: +1시간 힘들 때·비 올 때: 고개 구간은 탈출로가 거의 없음 → 비·눈 예보면 하루 미루거나, JR 세키→쓰게(간사이본선)→기부카와(구사쓰선)로 기차 우회
A27: 23 | B27: 12/26 | C27: 토 | D27: 오미 | E27: 구사쓰 | F27: 1박 | G27: 걷기 | H27: =IF('이동 상세'!H28="","",HYPERLINK('경로 좌표'!N22,'이동 상세'!H28)) -> 23.1 | I27: =IF('이동 상세'!H28="","",'이동 상세'!I28) -> 0.240625 | J27: =IF('이동 상세'!P28="","",'이동 상세'!P28) -> 0.3125 | K27: =IF('이동 상세'!Q28="","",'이동 상세'!Q28) -> 0.59479167 | L27: =IF('이동 상세'!S28="","",'이동 상세'!S28) -> 0.10706833 | M27: 평지 (긴 날) | N27: 51 이시베 52 구사쓰 | O27: 걷기)미나쿠치 → 이시베 → 구사쓰주쿠 본진 | Q27: 23 | R27: 12/26 | S27: 오미 | T27: 구사쓰 | U27: 미나쿠치 옛 거리, 요코타 와타시 조야토 (옛 나루터 큰 등롱, 이시베) 구사쓰주쿠 본진 (남은 본진 가운데 최대), 도카이도·나카센도 갈림길 | V27: 미나쿠치 시내: 오미규 (시가현 소고기) 덮밥·스테이크 구사쓰주쿠 본진 근처: 우바가모치 (명물 떡) | W27: 미나쿠치: 간표 (박고지), 구사쓰: 우바가모치 고카시: 시가라키야키 (도자기, 너구리 장식품이 유명) | X27: 미나쿠치는 에도 시대부터 박고지가 특산품. '교토를 떠나면 이시베에서 묵는다'는 말처럼 이시베는 교토에서 출발한 여행자가 첫 밤을 보내던 역참이었습니다. 도카이도와 나카센도는 구사쓰에서 합쳐져 교토로 갑니다. | Y27: 고난시 이시베는 공장과 주택이 섞인 교외 도시. 구사쓰는 교토·오사카 통근권이라 인구가 늘고 있는 도시이고, 리쓰메이칸대학 캠퍼스가 있습니다. | Z27: 미나쿠치 체크아웃 힘들 때·비 올 때: 오미철도 미나쿠치역, JR 구사쓰선 미쿠모·고세이·이시베·데라·구사쓰역
A28: 24 | B28: 12/27 | C28: 일 | D28: 오미 | E28: 오쓰 (세타·이시야마) | F28: 1박 | G28: 걷기 | H28: =IF('이동 상세'!H29="","",HYPERLINK('경로 좌표'!N23,'이동 상세'!H29)) -> 9.1 | I28: =IF('이동 상세'!H29="","",'이동 상세'!I29) -> 0.094791667 | J28: =IF('이동 상세'!P29="","",'이동 상세'!P29) -> 0.4375 | K28: =IF('이동 상세'!Q29="","",'이동 상세'!Q29) -> 0.57395833 | L28: =IF('이동 상세'!S29="","",'이동 상세'!S29) -> 0.12858167 | M28: 평지 (짧은 날) | O28: 걷기)구사쓰주쿠 본진 → 세타 가라하시 → 이시야마 | Q28: 24 | R28: 12/27 | S28: 오미 | T28: 오쓰 (세타·이시야마) | U28: 세타 가라하시, 오사카 고개 (옛 관문 터) 온천: 오고토 온천 (오쓰시 비와호 서쪽, JR 고세이선) | V28: 세타 가라하시 주변: 비와호 시지미 (재첩) 요리 | W28: 비와호: 후나즈시 (붕어 발효 초밥, 향이 강함) | X28: '세타의 가라하시를 차지하는 자가 천하를 차지한다'는 말이 있었을 만큼 비와호 남단의 군사·교통 요충지였습니다. | Y28: 오쓰는 시가현청 소재지로, 비와호는 간사이 약 1,450만 명의 물을 책임집니다. 걷기 도착점(세타 가라하시)에서 이시야마 숙소까지는 걸어서 약 10분. | Z28: 구사쓰 체크아웃 힘들 때·비 올 때: JR 비와코선 미나미쿠사쓰·세타·이시야마역
A29: 25 | B29: 12/28 | C29: 월 | D29: 오미 | E29: 교토 | F29: 3박 | G29: 걷기 | H29: =IF('이동 상세'!H30="","",HYPERLINK('경로 좌표'!N24,'이동 상세'!H30)) -> 19.6 | I29: =IF('이동 상세'!H30="","",'이동 상세'!I30) -> 0.20416667 | J29: =IF('이동 상세'!P30="","",'이동 상세'!P30) -> 0.35416667 | K29: =IF('이동 상세'!Q30="","",'이동 상세'!Q30) -> 0.6 | L29: =IF('이동 상세'!S30="","",'이동 상세'!S30) -> 0.10333 | M29: 완주! | N29: 53 오쓰 종점 교토 산조오하시 | O29: 걷기)이시야마 → 세타 → 오쓰 → 교토 산조오하시 (완주) → 고조 숙소 (약 1.6km) | Q29: 25 | R29: 12/28 | S29: 오미 | T29: 교토 | U29: 게아게 인클라인, 산조오하시 (도카이도 종점) | V29: 교토 산조 (산조오하시 근처, 완주 기념): 니신소바 (청어 메밀국수) | X29: 산조오하시는 도카이도와 나카센도의 종점으로, 1590년 도요토미 히데요시가 돌기둥 다리로 다시 지었습니다. 에도 시대 사람들은 니혼바시에서 약 2주 걸려 도착했습니다. | Y29: 산조오하시 일대는 가모강변을 따라 식당과 술집이 모인 교토 최대 번화가입니다. 드디어 도카이도 완주! 걷기를 오후 일찍 마치니, 남는 시간에 가모강변이나 기온을 가볍게 둘러봐도 좋습니다. | Z29: 도카이도 완주 · 이시야마 체크아웃 완주! 교토 3박 (완주한 날·예비일·관광일). 힘들 때·비 올 때: 게이한 게이신선 (오쓰·오타니·게아게역), JR 오쓰역
A30: 26 | B30: 12/29 | C30: 화 | D30: 교토 | E30: 교토 | F30: ↑ | G30: 관광 | H30: =IF('이동 상세'!H31="","",'이동 상세'!H31) | I30: =IF('이동 상세'!H31="","",'이동 상세'!I31) | J30: =IF('이동 상세'!P31="","",'이동 상세'!P31) | K30: =IF('이동 상세'!Q31="","",'이동 상세'!Q31) | L30: =IF('이동 상세'!S31="","",'이동 상세'!S31) | M30: 예비 | O30: 관광)예비일 (밀린 걷기) 또는 아라시야마·긴카쿠지 (선택) | Q30: 26 | R30: 12/29 | S30: 교토 | T30: 교토 | U30: 예비일: 비·부상으로 밀린 걷기를 이날로 메우기. 안 쓰면 아라시야마 (도게쓰교·대나무숲·덴류지)나 긴카쿠지·철학의 길 | V30: 아라시야마: 유도후 (두부 요리) 교토 시내: 오반자이 (교토 가정식 반찬) | X30: 아라시야마는 헤이안 시대 귀족들의 별장지였고, 덴류지는 1339년 아시카가 다카우지가 세운 절로 세계유산입니다. | Y30: 일정이 밀리지 않았다면 교토에서 하루 더 쉬는 날. 완주 다음 날이라 몸 상태를 보며 가볍게 움직이세요. | Z30: 비·부상으로 밀린 날이 있으면 이날로 메우고, 없으면 쉬거나 관광. 연말연시(12/29~1/3)에는 쉬는 식당·가게가 많으니 미리 확인.
A31: 27 | B31: 12/30 | C31: 수 | D31: 교토 | E31: 교토 | F31: ↑ | G31: 관광 | H31: =IF('이동 상세'!H32="","",'이동 상세'!H32) | I31: =IF('이동 상세'!H32="","",'이동 상세'!I32) | J31: =IF('이동 상세'!P32="","",'이동 상세'!P32) | K31: =IF('이동 상세'!Q32="","",'이동 상세'!Q32) | L31: =IF('이동 상세'!S32="","",'이동 상세'!S32) | M31: 관광 | O31: 관광)기요미즈데라·후시미이나리 신사 관광 | Q31: 27 | R31: 12/30 | S31: 교토 | T31: 교토 | U31: 기요미즈데라, 후시미이나리 신사, 니시키 시장 | V31: 니시키 시장: 시장 먹거리 기요미즈데라 주변·난젠지 근처: 유도후 (두부 요리) | W31: 교토: 쓰케모노 (절임 채소), 야쓰하시 (계피 떡과자) 기요미즈야키 (도자기), 니시진오리 (비단 직물) | X31: 794년부터 1,000년 넘게 일본의 수도였던 도시입니다. | Y31: 일본 최대 관광 도시이자 대학이 많은 학생의 도시. 연말 니시키 시장은 새해 음식을 사려는 사람들로 가장 붐빕니다. | Z31: 연말연시 휴무 주의 (식당·가게 미리 확인).
A32: 28 | B32: 12/31 | C32: 목 | D32: 교토·고베 | E32: 아리마 온천 | F32: 2박 | G32: 교통 | H32: =IF('이동 상세'!H33="","",'이동 상세'!H33) | I32: =IF('이동 상세'!H33="","",'이동 상세'!I33) | J32: =IF('이동 상세'!P33="","",'이동 상세'!P33) | K32: =IF('이동 상세'!Q33="","",'이동 상세'!Q33) | L32: =IF('이동 상세'!S33="","",'이동 상세'!S33) | M32: 섣달그믐, 온천 이동 | O32: 교통)교토역 → 아리마 온천 (직행 고속버스) 관광)킨노유·긴노유, 온천 거리 | Q32: 28 | R32: 12/31 | S32: 교토·고베 | T32: 아리마 온천 | U32: 아리마 온천 거리 (유모토자카), 온천: 킨노유 (철분이 많은 적갈색 '금탕') 긴노유 (투명한 '은탕') - 두 곳 모두 1월 1일 휴관이라 오늘(12/31) 다녀오기 | V32: 아리마 온천 거리: 아리마 사이다, 갓 구운 탄산센베이 숙소·식당 (섣달그믐): 도시코시소바 | W32: 아리마: 탄산센베이, 닌교후데 (붓을 세우면 인형이 튀어나오는 전통 붓) | X32: 일본에서 가장 오래된 온천 가운데 하나로, 도요토미 히데요시가 여러 번 찾아와 온천을 정비했습니다. | Y32: 고베시에 속한 간사이의 대표 온천 마을. 오사카·고베에서 1시간 안에 갈 수 있어 연말연시에 특히 붐빕니다. 섣달그믐 밤에는 긴노유 족욕탕 주변에서 작은 불꽃놀이나 행사가 열리기도 합니다. | Z32: 교통 이유: 섣달그믐에 교토에서 아리마 온천으로 직행 고속버스(약 1시간 15분)로 이동해 새해 첫날까지 온천에서 보냅니다. 하루 2편뿐미리 예약, 만석이면 JR 경유(약 1시간 40분, 환승 3회). 섣달그믐. 연말연시 휴무 주의. 공공 온천은 1/1 휴관이라 오늘 다녀오기.
A33: 29 | B33: 1/1 | C33: 금 | D33: 고베 | E33: 아리마 온천 | F33: ↑ | G33: 휴식 | H33: =IF('이동 상세'!H34="","",'이동 상세'!H34) | I33: =IF('이동 상세'!H34="","",'이동 상세'!I34) | J33: =IF('이동 상세'!P34="","",'이동 상세'!P34) | K33: =IF('이동 상세'!Q34="","",'이동 상세'!Q34) | L33: =IF('이동 상세'!S34="","",'이동 상세'!S34) | M33: 새해 첫날, 온천 | O33: 관광)새해 첫 참배·온천 | Q33: 29 | R33: 1/1 | S33: 고베 | T33: 아리마 온천 | U33: 아리마 온천 거리, 새해 첫 참배 (가까운 신사) 온천: 숙소 온천 (공공 온천 킨노유·긴노유는 1월 1일 휴관) | V33: 아리마 온천 거리: 아리마 사이다, 새해 첫 식사 | X33: 일본에서 가장 오래된 온천 가운데 하나로, 도요토미 히데요시가 여러 번 찾아와 온천을 정비했습니다. | Y33: 새해 첫날은 숙소·온천이 가장 붐비는 시기입니다. 느긋하게 온천과 참배로 하루를 보내기 좋습니다. | Z33: 새해 첫날. 숙소·교통 요금이 비싸고 붐빔.
A34: 30 | B34: 1/2 | C34: 토 | D34: 오사카 | E34: 오사카 (난바) | F34: 1박 | G34: 교통 | H34: =IF('이동 상세'!H35="","",'이동 상세'!H35) | I34: =IF('이동 상세'!H35="","",'이동 상세'!I35) | J34: =IF('이동 상세'!P35="","",'이동 상세'!P35) | K34: =IF('이동 상세'!Q35="","",'이동 상세'!Q35) | L34: =IF('이동 상세'!S35="","",'이동 상세'!S35) | M34: 오사카 이동 | O34: 교통)아리마 온천 → 오사카 우메다 (고속버스), 교통)우메다 → 난바 (지하철) 관광)신세카이·도톤보리·오사카성 | Q34: 30 | R34: 1/2 | S34: 오사카 | T34: 오사카 (난바) | U34: 신세카이, 쓰텐카쿠, 도톤보리, 오사카성 온천: 스파월드 (세계 여러 나라 테마의 대형 온천 시설) | V34: 신세카이 (쓰텐카쿠 아래): 구시카쓰 (꼬치 튀김) 도톤보리: 다코야키, 오코노미야키 | X34: 오사카성은 도요토미 히데요시가 1583년 쌓은 성으로, 이에야스와의 오사카 전투 끝에 불탔다가 이후 다시 지어졌습니다. | Y34: 오사카는 일본 제2의 도시이자 '먹다 망하는 도시'라 불리는 음식의 도시. 2025년 오사카·간사이 엑스포가 열렸습니다. | Z34: 교통 이유: 아리마 온천에서 비행 전날 오사카로 이동 (고속버스 약 1시간, 우메다 도착 후 지하철로 난바). 신세카이·도톤보리·오사카성은 이날 오후에 둘러봅니다. 오사카성 천수각은 12/28~1/1 휴관, 오늘(1/2)부터 개관. 연말연시 휴무가 1/3까지 이어지는 가게도 있으니 확인.
A35: 31 | B35: 1/3 | C35: 일 | D35: - | E35: - | F35: - | G35: 귀국 | H35: =IF('이동 상세'!H36="","",'이동 상세'!H36) | I35: =IF('이동 상세'!H36="","",'이동 상세'!I36) | J35: =IF('이동 상세'!P36="","",'이동 상세'!P36) | K35: =IF('이동 상세'!Q36="","",'이동 상세'!Q36) | L35: =IF('이동 상세'!S36="","",'이동 상세'!S36) | M35: 귀국 | O35: 교통)난바역 → 간사이공항역 (난카이 라피트) | Q35: 31 | R35: 1/3 | S35: - | T35: - | Z35: 교통 이유: 공항으로 이동.
A37: 합계와 평균
A38: 걷기 일수 (일) | E38: =COUNT('이동 상세'!H6:H36) -> 19
A39: 걷기 총 거리 (km) | E39: =SUM('이동 상세'!H6:H36) -> 353.5
A40: 걷기 하루 평균 거리 (km) | E40: =AVERAGE('이동 상세'!H6:H36) -> 18.605263
A41: 걷기 하루 평균 시간 | E41: =AVERAGE('이동 상세'!H6:H36)/'이동 상세'!$C$2/24 -> 0.19380482
A42: 걷기 가장 긴 날 (km) | E42: =MAX('이동 상세'!H6:H36) -> 26.3
...

Sheet 이동 상세
A1: 이동 상세 (걷기·교통 구간별 거리와 시간)
A2: 걷기 속도 (km/h) | C2: 4 | D2: ← 순수 걷기 기준 가정값(직접 수정 가능). 바꾸면 걷기 시간·예상 도착 시각이 다시 계산됩니다. 쉬는 시간 포함 시 하루 5~6시간, 산길은 +1시간.
A3: 환율 (원/엔) | C3: 8.445 | D3: ← 원화 환산용 가정값(직접 수정 가능). 교통비는 2026년 기준 대략값이며 IC카드 요금과 조금 다를 수 있습니다.
A4: 출발 시각 원칙 | D4: 15km 미만·고개 없는 날은 늦잠(9:30~10:30), 15~20km는 8:30, 20km 이상이거나 고개가 있는 날은 7:30~8:00. 노란 '걷기 출발' 칸을 그날 컨디션에 맞게 고치면 도착·해 지기 전 여유가 다시 계산됩니다.
A5: 일차 | B5: 날짜 | C5: 요일 | D5: 권역 | E5: 숙박 지역 | F5: 구분 | G5: 걷기 구간 (누르면 구글 지도 도보 경로) | H5: 걷기 거리 (km) | I5: 걷기 시간 | J5: 교통 구간 (출발 → 도착, 노선) | K5: 교통 거리 (km) | L5: 교통 시간 (분) | M5: 탑승 횟수 | N5: 교통비 (엔, 대략) | O5: 메모 | P5: 걷기 출발 (예상) | Q5: 도착 (예상) | R5: 일몰 (도착지) | S5: 해 지기 전 여유 | T5: 숙소 후보 1 | U5: 숙소 후보 2 | V5: 박수 | W5: 아고다 검색 (날짜 포함)
A6: 1 | B6: 12/4 | C6: 금 | D6: 도쿄 | E6: 도쿄 시나가와 | F6: 교통 | I6: =IF(H6="","",H6/$C$2/24) | J6: 하네다공항역 → 시나가와역 (게이큐) | K6: 15 | L6: 15 | M6: 1 | N6: 330 | T6: 시나가와슈쿠 게스트하우스, 60,178원/박 신반바역 573m, 옛 시나가와 역참 거리 | U6: 아우어즈 인 한,큐149,645원/박 오이마치역 106m (시나가와역에서 1정거장) | V6: 2 | W6: 아고다에서 보기
A7: 2 | B7: 12/5 | C7: 토 | D7: 도쿄 | E7: 도쿄 시나가와 | F7: 관광 | I7: =IF(H7="","",H7/$C$2/24) | J7: 도쿄 시내 지하철 (합계 제외) | M7: 0 | N7: 800 | O7: 도쿄 지하철 24시간권 기준 | T7: (위와 같음)
A8: 3 | B8: 12/6 | C8: 일 | D8: 하코네·후지 | E8: 오다와라 | F8: 교통+걷기 | G8: =HYPERLINK('경로 좌표'!N6,"오이소 → 오다와라 (호텔 포쉬)") -> 오이소 → 오다와라 (호텔 포쉬) | H8: 16.9 | I8: =IF(H8="","",H8/$C$2/24) -> 0.17604167 | J8: 시나가와역 → 오이소역 (JR 도카이도선) | K8: 61 | L8: 55 | M8: 1 | N8: 1100 | P8: 0.35416667 | Q8: =P8+I8+1/24 -> 0.571875 | R8: 0.68811 | S8: =R8-Q8 -> 0.116235 | T8: 토요코인 오다와라에키 히가시구치 76,555원/박, 오다와라역 324m 비즈니스 호텔, 아침 무료 | U8: HOTEL POSH, 72,618원/박 오다와라역 271m, 호텔 | V8: 1 | W8: 아고다에서 보기
A9: 4 | B9: 12/7 | C9: 월 | D9: 하코네·후지 | E9: 하코네 (아시노호수) | F9: 걷기 | G9: =HYPERLINK('경로 좌표'!N7,"오다와라 → 하코네 옛 돌길 → 아마자케차야 → 모토하코네 (RoheN)") -> 오다와라 → 하코네 옛 돌길 → 아마자케차야 → 모토하코네 (RoheN) | H9: 16.9 | I9: =IF(H9="","",H9/$C$2/24) -> 0.17604167 | M9: 0 | O9: 산길: +1시간 결빙·폭설 시 플랜 B: 하코네 토잔 버스 | P9: 0.33333333 | Q9: =P9+I9+1.5/24 -> 0.571875 | R9: 0.68856 | S9: =R9-Q9 -> 0.116685 | T9: RoheN ASHINOKO, 45,511원/박 오시바 버스정류장 근처, 하코네 관소에서 약 1.4km (다인실 여부 확인) | U9: 오다큐 호텔 데 야마 하코네 레이크사이드 193,503원/박 ★ 쉬는 날·온천 추천 아시노호수 호숫가, 관소에서 약 1.4km | V9: 2 | W9: 아고다에서 보기
A10: 5 | B10: 12/8 | C10: 화 | D10: 하코네·후지 | E10: 하코네 (아시노호수) | F10: 휴식 | I10: =IF(H10="","",H10/$C$2/24) | M10: 0 | O10: 결빙·폭설 예보가 있으면 이날을 예비일로 써서 하루 늦게 고개를 넘어도 됨 | T10: (위와 같음)
A11: 6 | B11: 12/9 | C11: 수 | D11: 하코네·후지 | E11: 미시마 | F11: 걷기 | G11: =HYPERLINK('경로 좌표'!N8,"모토하코네 → 하코네 관소 → 하코네 고개 → 야마나카성터 → 미시마") -> 모토하코네 → 하코네 관소 → 하코네 고개 → 야마나카성터 → 미시마 | H11: 18.4 | I11: =IF(H11="","",H11/$C$2/24) -> 0.19166667 | M11: 0 | O11: 산길: +1시간 결빙·폭설 시 플랜 B: 버스로 미시마까지 | P11: 0.33333333 | Q11: =P11+I11+1.5/24 -> 0.5875 | R11: 0.68915 | S11: =R11-Q11 -> 0.10165 | T11: 도미 인 미시마 핫 스프링, 101,402원/박 미시마역 근처, 천연 온천 대욕장 | U11: Hotel Gee Haive, 38,164원/박 | V11: 1 | W11: 아고다에서 보기
A12: 7 | B12: 12/10 | C12: 목 | D12: 하코네·후지 | E12: 후지 요시와라 | F12: 걷기 | G12: =HYPERLINK('경로 좌표'!N9,"미시마 → 누마즈 → 센본마쓰바라 → 하라 → 요시와라 (호텔 니시무라)") -> 미시마 → 누마즈 → 센본마쓰바라 → 하라 → 요시와라 (호텔 니시무라) | H12: 26.3 | I12: =IF(H12="","",H12/$C$2/24) -> 0.27395833 | M12: 0 | O12: 미시마 체크아웃 | P12: 0.29166667 | Q12: =P12+I12+1/24 -> 0.60729167 | R12: 0.68981 | S12: =R12-Q12 -> 0.082518333 | T12: 호텔 니시무라 (Hotel Nishimura) 59,787원/박, 요시와라혼초역에서 약 1.2km | U12: 쿠레타케 인 후지산, 56,050원/박 요시와라혼초역에서 약 0.9km | V12: 1 | W12: 아고다에서 보기
A13: 8 | B13: 12/11 | C13: 금 | D13: 하코네·후지 | E13: 오키쓰 | F13: 걷기 | G13: =HYPERLINK('경로 좌표'!N10,"요시와라 → 후지강 다리 → 간바라 → 유이 → 삿타 고개 → 오키쓰") -> 요시와라 → 후지강 다리 → 간바라 → 유이 → 삿타 고개 → 오키쓰 | H13: 21.5 | I13: =IF(H13="","",H13/$C$2/24) -> 0.22395833 | M13: 0 | O13: 요시와라 체크아웃 | P13: 0.33333333 | Q13: =P13+I13+1.5/24 -> 0.61979167 | R13: 0.69051 | S13: =R13-Q13 -> 0.070718333 | T13: 쿠어 앤 호텔 스루가 (Kur and Hotel Suruga) 59,409원/박, 오키쓰역 근처, 세이켄지까지 약 1km, 온천·스파 호텔 (2박 기준 요금) | U13: Guest House NOMAYADO, 121,479원/박 유이 본진 공원 동쪽 약 1.9km (걷는 길 위) 대안: 지치면 유이에서 묵기 | V13: 2 | W13: 아고다에서 보기
A14: 9 | B14: 12/12 | C14: 토 | D14: 시즈오카 | E14: 오키쓰 | F14: 휴식 | I14: =IF(H14="","",H14/$C$2/24) | J14: 오키쓰 → 미호노마쓰바라 (버스, 선택·합계 제외) | M14: 0 | T14: (위와 같음)
A15: 10 | B15: 12/13 | C15: 일 | D15: 시즈오카 | E15: 시즈오카 | F15: 걷기 | G15: =HYPERLINK('경로 좌표'!N11,"오키쓰 → 에지리 (시미즈) → 구사나기 → 시즈오카 (후추)") -> 오키쓰 → 에지리 (시미즈) → 구사나기 → 시즈오카 (후추) | H15: 19.1 | I15: =IF(H15="","",H15/$C$2/24) -> 0.19895833 | M15: 0 | O15: 오키쓰 체크아웃 | P15: 0.35416667 | Q15: =P15+I15+1/24 -> 0.59479167 | R15: 0.69135 | S15: =R15-Q15 -> 0.096558333 | T15: 호텔 가든 스퀘어 시즈오카, 58,411원/박 시즈오카역 약 400m | U15: KOKO 호텔 시즈오카 8.5점 · 후기 7,008건 · 46,209원/박 시즈오카역 약 800m | V15: 1 | W15: 아고다에서 보기
A16: 11 | B16: 12/14 | C16: 월 | D16: 시즈오카 | E16: 후지에다 | F16: 걷기 | G16: =HYPERLINK('경로 좌표'!N12,"시즈오카 → 마리코 (조지야 점심) → 우쓰노야 고개 → 오카베 → 후지에다") -> 시즈오카 → 마리코 (조지야 점심) → 우쓰노야 고개 → 오카베 → 후지에다 | H16: 23.2 | I16: =IF(H16="","",H16/$C$2/24) -> 0.24166667 | M16: 0 | O16: 시즈오카 체크아웃 | P16: 0.3125 | Q16: =P16+I16+1.5/24 -> 0.61666667 | R16: 0.69211 | S16: =R16-Q16 -> 0.075443333 | T16: 호텔 슈퍼 도마리, 62,904원/박 후지에다역 약 400m | U16: 토요코인 후지에다에키 기타구치 8.3점 · 후기 555건 · 58,964원/박 후지에다역 약 100m 아침 무료 ※ 하루 앞당겨지기 전 날짜 요금, 재확인 필요 | V16: 1 | W16: 아고다에서 보기
A17: 12 | B17: 12/15 | C17: 화 | D17: 시즈오카 | E17: 시마다 | F17: 걷기 | G17: =HYPERLINK('경로 좌표'!N13,"후지에다 → 시마다역") -> 후지에다 → 시마다역 | H17: 7.8 | I17: =IF(H17="","",H17/$C$2/24) -> 0.08125 | M17: 0 | O17: 후지에다 체크아웃 | P17: 0.4375 | Q17: =P17+I17+1/24 -> 0.56041667 | R17: 0.69255 | S17: =R17-Q17 -> 0.13213333 | T17: 호텔 루트인 시마다 에키마에, 57,928원/박 시마다역 약 400m, ★ 추천: 대욕장 | U17: 하타고 인 시즈오카 요시다 IC (HATAGO INN Shizuoka Yoshida IC) 8.8점 · 후기 5,438건 · 요금: 아고다에서 확인 시마다역에서 약 5km 남동쪽 (요시다 IC) 직접 고른 숙소. 2026-10-26 확인 때 이 날짜 아고다 예약 불가, 옛길에서 떨어져 다음 날이 약 27km로 늘어 대신 루트인으로 둠 | V17: 1 | W17: 아고다에서 보기
A18: 13 | B18: 12/16 | C18: 수 | D18: 시즈오카 | E18: 가케가와 | F18: 걷기 | G18: =HYPERLINK('경로 좌표'!N14,"시마다 → 호라이교 → 가나야 돌길 → 닛사카 → 가케가와역") -> 시마다 → 호라이교 → 가나야 돌길 → 닛사카 → 가케가와역 | H18: 22.6 | I18: =IF(H18="","",H18/$C$2/24) -> 0.23541667 | M18: 0 | O18: 시마다 체크아웃 | P18: 0.3125 | Q18: =P18+I18+1.5/24 -> 0.61041667 | R18: 0.69332 | S18: =R18-Q18 -> 0.082903333 | T18: 내추럴 핫 스프링 스파 도미 인 익스프레스 가케가와, 72,196원/박 가케가와역 약 550m, 천연 온천 대욕장 | U18: 토요코인 가케가와에키 신칸센미나미구치 8.2점 · 후기 306건 · 61,284원/박 가케가와역 남쪽 출구 비즈니스 호텔, 아침 무료 ※ 하루 앞당겨지기 전 날짜 요금, 재확인 필요 | V18: 1 | W18: 아고다에서 보기
A19: 14 | B19: 12/17 | C19: 목 | D19: 엔슈 | E19: 하마나호 (와시즈) | F19: 교통+걷기 | G19: =HYPERLINK('경로 좌표'!N15,"하마마쓰 → 마이사카 → 벤텐지마 → 아라이 관소 → 와시즈 (호숫가 숙소)") -> 하마마쓰 → 마이사카 → 벤텐지마 → 아라이 관소 → 와시즈 (호숫가 숙소) | H19: 20.8 | I19: =IF(H19="","",H19/$C$2/24) -> 0.21666667 | J19: 가케가와역 → 하마마쓰역 (JR 도카이도선) | K19: 27.8 | L19: 30 | M19: 1 | N19: 510 | O19: 가케가와→하마마쓰 (JR) 가케가와 체크아웃 | P19: 0.33333333 | Q19: =P19+I19+1/24 -> 0.59166667 | R19: 0.69498 | S19: =R19-Q19 -> 0.10331333 | T19: 호텔 난반 하마나코· 요금: 확인 와시즈역 근처, 아라이 관소에서 약 3km | U19: 호텔 디 오션 (벤텐 리조트) 7.7점 · 후기 925건 · 74,660원/박 벤텐지마, 약 0.8km 호수 전망·온천 대욕장, 뷔페 | V19: 2 | W19: 아고다에서 보기
A20: 15 | B20: 12/18 | C20: 금 | D20: 엔슈 | E20: 하마나호 (와시즈) | F20: 휴식 | I20: =IF(H20="","",H20/$C$2/24) | J20: 와시즈역 ↔ 하마마쓰역 (JR) + 간잔지 온천 버스 (선택, 합계 제외) | M20: 0 | T20: (위와 같음)
A21: 16 | B21: 12/19 | C21: 토 | D21: 미카와 | E21: 도요하시 | F21: 걷기 | G21: =HYPERLINK('경로 좌표'!N16,"와시즈 → 시라스카 → 시오미자카 → 후타가와 본진 → 도요하시") -> 와시즈 → 시라스카 → 시오미자카 → 후타가와 본진 → 도요하시 | H21: 23 | I21: =IF(H21="","",H21/$C$2/24) -> 0.23958333 | M21: 0 | O21: 하마나호 체크아웃 | P21: 0.3125 | Q21: =P21+I21+1/24 -> 0.59375 | R21: 0.69588 | S21: =R21-Q21 -> 0.10213 | T21: 호텔 어소시아 도요하시 8.9점 · 후기 3,866건 · 99,036원/박 도요하시역 101m 역 바로 옆 ※ 하루 앞당겨지기 전 날짜 요금, 재확인 필요 | U21: 도미 인 익스프레스 도요하시 핫 스프링 8.7점 · 후기 3,016건 · 74,041원/박 신도요하시역 812m 천연 온천 대욕장 (23km 걸은 날 추천) ※ 하루 앞당겨지기 전 날짜 요금, 재확인 필요 | V21: 2 | W21: 아고다에서 보기
A22: 17 | B22: 12/20 | C22: 일 | D22: 미카와 | E22: 도요하시 | F22: 걷기+교통 | G22: =HYPERLINK('경로 좌표'!N17,"도요하시 → 고유 소나무 가로수길 → 아카사카") -> 도요하시 → 고유 소나무 가로수길 → 아카사카 | H22: 13.7 | I22: =IF(H22="","",H22/$C$2/24) -> 0.14270833 | J22: 메이덴아카사카역 → 도요하시역 (메이테쓰) | K22: 11 | L22: 18 | M22: 1 | N22: 400 | P22: 0.39583333 | Q22: =P22+I22+1/24 -> 0.58020833 | R22: 0.69621 | S22: =R22-Q22 -> 0.11600167 | T22: (위와 같음)
A23: 18 | B23: 12/21 | C23: 월 | D23: 미카와 | E23: 오카자키 | F23: 교통+걷기 | G23: =HYPERLINK('경로 좌표'!N18,"아카사카 → 후지카와 → 오카자키성 → 히가시오카자키 (숙소)") -> 아카사카 → 후지카와 → 오카자키성 → 히가시오카자키 (숙소) | H23: 19.9 | I23: =IF(H23="","",H23/$C$2/24) -> 0.20729167 | J23: 도요하시역 → 메이덴아카사카역 (메이테쓰) | K23: 11 | L23: 18 | M23: 1 | N23: 400 | O23: 도요하시 체크아웃 | P23: 0.35416667 | Q23: =P23+I23+1/24 -> 0.603125 | R23: 0.69674 | S23: =R23-Q23 -> 0.093615 | T23: Grand Inn Higashi-Okazaki, 65,709원 히가시오카자키역 169m, 비즈니스 호텔 | U23: 호텔 라이브맥스 오카자키, 18,292원/박 히가시오카자키역 447m | V23: 1 | W23: 아고다에서 보기
A24: 19 | B24: 12/22 | C24: 화 | D24: 나고야 | E24: 나고야 | F24: 교통+걷기+교통 | G24: =HYPERLINK('경로 좌표'!N19,"지류 → 아리마쓰 옛 거리 → 나루미 → 아쓰타 신궁") -> 지류 → 아리마쓰 옛 거리 → 나루미 → 아쓰타 신궁 | H24: 19.8 | I24: =IF(H24="","",H24/$C$2/24) -> 0.20625 | J24: 히가시오카자키역 → 지류역 / 진구마에역 → 나고야역 (메이테쓰) | K24: 16 | L24: 22 | M24: 2 | N24: 620 | O24: 오카자키 체크아웃 | P24: 0.35416667 | Q24: =P24+I24+1/24 -> 0.60208333 | R24: 0.6975 | S24: =R24-Q24 -> 0.095416667 | T24: 비아 인 나고야 에키마에 츠바키초 70,326원/박, 나고야역 약 300m JR 서일본 계열 비즈니스 호텔 | U24: 산코 인 나고야 신칸센구치 8.5점 · 후기 6,751건 · 71,665원/박 나고야역 약 200m 비즈니스 호텔 ※ 하루 앞당겨지기 전 날짜 요금, 재확인 필요 | V24: 1 | W24: 아고다에서 보기
A25: 20 | B25: 12/23 | C25: 수 | D25: 나고야 | E25: 구와나 | F25: 휴식 | I25: =IF(H25="","",H25/$C$2/24) | J25: 나고야역 → 구와나역 (JR·긴테쓰) | K25: 24 | L25: 25 | M25: 1 | N25: 500 | O25: 나고야→구와나 (JR·긴테쓰, 대략), 나가시마 온천 버스는 별도 나고야 체크아웃 | T25: 산코 인 구와나 에키마에, 50,916원/박 구와나역 약 200m, 나가시마 온천은 당일 입욕 | U25: 구와나 파크 호텔 7.6점 · 후기 162건 · 51,987원/박 구와나역 약 300m 호텔 ※ 하루 앞당겨지기 전 날짜 요금, 재확인 필요 | V25: 1 | W25: 아고다에서 보기
A26: 21 | B26: 12/24 | C26: 목 | D26: 스즈카 | E26: 가메야마 (세키 입구) | F26: 교통+걷기 | G26: =HYPERLINK('경로 좌표'!N20,"가사도 → 쇼노 → 가메야마 → 세키 입구 (칸데오 호텔)") -> 가사도 → 쇼노 → 가메야마 → 세키 입구 (칸데오 호텔) | H26: 13.7 | I26: =IF(H26="","",H26/$C$2/24) -> 0.14270833 | J26: 구와나역 → 가사도역 (JR 간사이본선) | K26: 30 | L26: 40 | M26: 1 | N26: 600 | O26: 구와나→가사도 (대략) 구와나 체크아웃 | P26: 0.39583333 | Q26: =P26+I26+1/24 -> 0.58020833 | R26: 0.7001 | S26: =R26-Q26 -> 0.11989167 | T26: 칸데오 호텔 가메야마 8.0점 · 후기 954건 · 39,230원/박 세키주쿠에서 약 1.8km (세키 IC 쪽, 걸어서 이동) ★ 추천: 대욕장. 세키주쿠 안 게스트하우스 '이시가키야'는 아고다에 없어 직접 연락 필요 ※ 하루 앞당겨지기 전 날짜 요금, 재확인 필요 | U26: 호텔 루트인 가메야마 인터 8.2점 · 후기 367건 · 49,841원/박 세키주쿠에서 약 2.5km 대욕장 ※ 하루 앞당겨지기 전 날짜 요금, 재확인 필요 | V26: 1 | W26: 아고다에서 보기
A27: 22 | B27: 12/25 | C27: 금 | D27: 오미 | E27: 미나쿠치 | F27: 걷기+교통 | G27: =HYPERLINK('경로 좌표'!N21,"세키 입구 → 세키주쿠 옛 거리 → 사카시타 → 스즈카 고개 → 쓰치야마") -> 세키 입구 → 세키주쿠 옛 거리 → 사카시타 → 스즈카 고개 → 쓰치야마 | H27: 18.1 | I27: =IF(H27="","",H27/$C$2/24) -> 0.18854167 | J27: 쓰치야마 → 기부카와역 (버스) → 미나쿠치 (오미철도) | K27: 16 | L27: 37 | M27: 2 | N27: 900 | O27: 버스 + 오미철도 산길: +1시간 가메야마 체크아웃 | P27: 0.33333333 | Q27: =P27+I27+1.5/24 -> 0.584375 | R27: 0.70071 | S27: =R27-Q27 -> 0.116335 | T27: 호텔 루트인 고카 미나쿠치 8.2점 · 후기 1,230건 · 66,958원/박 미나쿠치이시바시역 1.5km (국도 1호선변) 비즈니스 호텔, 대욕장 ※ 하루 앞당겨지기 전 날짜 요금, 재확인 필요 | U27: 미나쿠치 센추리 호텔, 68,438원/박 미나쿠치이시바시역 860m 시내 중심 | V27: 1 | W27: 아고다에서 보기
A28: 23 | B28: 12/26 | C28: 토 | D28: 오미 | E28: 구사쓰 | F28: 걷기 | G28: =HYPERLINK('경로 좌표'!N22,"미나쿠치 → 이시베 → 구사쓰주쿠 본진 → 구사쓰역") -> 미나쿠치 → 이시베 → 구사쓰주쿠 본진 → 구사쓰역 | H28: 23.1 | I28: =IF(H28="","",H28/$C$2/24) -> 0.240625 | M28: 0 | O28: 미나쿠치 체크아웃 | P28: 0.3125 | Q28: =P28+I28+1/24 -> 0.59479167 | R28: 0.70186 | S28: =R28-Q28 -> 0.10706833 | T28: 호텔 보스턴 플라자 구사쓰 비와코 53,055원/박, 구사쓰역 107m 역 바로 옆, 가성비 | U28: 구사쓰 에스토피아 호텔 8.3점 · 후기 966건 · 75,250원/박 구사쓰역 322m 호텔 ※ 하루 앞당겨지기 전 날짜 요금, 재확인 필요 | V28: 1 | W28: 아고다에서 보기
A29: 24 | B29: 12/27 | C29: 일 | D29: 오미 | E29: 오쓰 (세타·이시야마) | F29: 걷기 | G29: =HYPERLINK('경로 좌표'!N23,"구사쓰역 → 세타 가라하시 → 이시야마") -> 구사쓰역 → 세타 가라하시 → 이시야마 | H29: 9.1 | I29: =IF(H29="","",H29/$C$2/24) -> 0.094791667 | M29: 0 | O29: 구사쓰 체크아웃 | P29: 0.4375 | Q29: =P29+I29+1/24 -> 0.57395833 | R29: 0.70254 | S29: =R29-Q29 -> 0.12858167 | T29: 르 락 호텔 오쓰 이시야마, 77,897원/박 게이한 이시야마역 127m, 세타 가라하시 약 750m | U29: APA 호텔 비와코 세타에키마에 8.0점 · 후기 1,965건 · 72,470원/박 JR 세타역 119m 비즈니스 호텔 ※ 하루 앞당겨지기 전 날짜 요금, 재확인 필요 | V29: 1 | W29: 아고다에서 보기
A30: 25 | B30: 12/28 | C30: 월 | D30: 오미 | E30: 교토 | F30: 걷기 | G30: =HYPERLINK('경로 좌표'!N24,"이시야마 → 세타 → 오쓰 → 교토 산조오하시 → 고조 (숙소)") -> 이시야마 → 세타 → 오쓰 → 교토 산조오하시 → 고조 (숙소) | H30: 19.6 | I30: =IF(H30="","",H30/$C$2/24) -> 0.20416667 | M30: 0 | O30: 도카이도 완주 · 이시야마 체크아웃 | P30: 0.35416667 | Q30: =P30+I30+1/24 -> 0.6 | R30: 0.70333 | S30: =R30-Q30 -> 0.10333 | T30: 소테츠 프레사 인 교토-기요미즈 고조 요금: 확인, 게이한 기요미즈고조역 근처, 산조오하시에서 약 1.6km | U30: 호텔 그란 Ms 교토 8.6점 · 후기 14,020건 · 86,676원/박 교토시야쿠쇼마에역 126m, 산조오하시 약 400m 완주 지점 바로 근처 ※ 하루 앞당겨지기 전 날짜 요금, 재확인 필요 | V30: 3 | W30: 아고다에서 보기
A31: 26 | B31: 12/29 | C31: 화 | D31: 교토 | E31: 교토 | F31: 관광 | I31: =IF(H31="","",H31/$C$2/24) | J31: 교토 시내 버스·전철 (합계 제외) | M31: 0 | T31: (위와 같음)
A32: 27 | B32: 12/30 | C32: 수 | D32: 교토 | E32: 교토 | F32: 관광 | I32: =IF(H32="","",H32/$C$2/24) | J32: 교토 시내 버스·지하철 (합계 제외) | M32: 0 | N32: 1100 | O32: 교토 지하철·버스 1일권 기준 | T32: (위와 같음)
A33: 28 | B33: 12/31 | C33: 목 | D33: 교토·고베 | E33: 아리마 온천 | F33: 교통 | I33: =IF(H33="","",H33/$C$2/24) | J33: 교토역 → 아리마 온천 (직행 고속버스, 하루 2편·예약 권장) | K33: 75 | L33: 75 | M33: 1 | N33: 1850 | O33: 직행 고속버스 1,850엔 (JR 경유 시 1,830엔) 교토 체크아웃 · 아리마로 바로 이동 | T33: Brücke Arima KOBE, 64,536원/박 아리마온센역 889m 게스트하우스형, 새해에도 비교적 저렴 | U33: 고야도 우라쿠 8.9점 · 후기 1,069건 · 241,925원/박 온천 거리 중심 작은 숙소 | V33: 2 | W33: 아고다에서 보기
A34: 29 | B34: 1/1 | C34: 금 | D34: 고베 | E34: 아리마 온천 | F34: 휴식 | I34: =IF(H34="","",H34/$C$2/24) | M34: 0 | T34: (위와 같음)
A35: 30 | B35: 1/2 | C35: 토 | D35: 오사카 | E35: 오사카 (난바) | F35: 교통 | I35: =IF(H35="","",H35/$C$2/24) | J35: 아리마 온천 → 오사카 우메다 (고속버스) 우메다 → 난바 (지하철 미도스지선) | K35: 36 | L35: 75 | M35: 2 | N35: 1640 | O35: 고속버스 1,400엔 + 지하철 아리마 체크아웃 | T35: 토호 호텔 난바 모토마치 8.6점 · 후기 6,331건 · 59,286원/박 JR 난바역 417m 다음 날 공항 가기 편함 | U35: APA 호텔 난바 미나미 에비스초 에키 신세카이 69,733원/박, 에비스초역 19m 비즈니스 호텔 | V35: 1 | W35: 아고다에서 보기
A36: 31 | B36: 1/3 | C36: 일 | D36: - | E36: - | F36: 귀국 | I36: =IF(H36="","",H36/$C$2/24) | J36: 난바역 → 간사이공항역 (난카이 라피트) | K36: 43 | L36: 40 | M36: 1 | N36: 1490 | O36: 난카이 라피트 (지정석 포함)
A38: 합계와 평균
A39: 걷기 일수 (일) | E39: =COUNT(H6:H36) -> 19
A40: 걷기 총 거리 (km) | E40: =SUM(H6:H36) -> 353.5
A41: 걷기 하루 평균 거리 (km) | E41: =AVERAGE(H6:H36) -> 18.605263
...

Sheet 여행 전 알아둘 것
A1: 여행 전 알아둘 것
A2: 빨간 굵은 글씨 = 꼭 알아야 할 부분
A4: 분류 | B4: 제목 | C4: 내용
A5: 입국 | B5: 비자·입국 등록 | C5: 한국 여권은 90일까지 무비자. 출국 전 'Visit Japan Web'에 입국·세관 정보를 등록해 두면 공항에서 QR 코드로 빠르게 통과합니다.
A6: 입국 | B6: 출국세 | C6: 2026년 7월부터 일본 출국세(국제관광여객세)가 1,000엔에서 3,000엔으로 올랐습니다. 보통 항공권 값에 포함되어 따로 낼 일은 없습니다.
A7: 교통 | B7: 교통카드 | C7: 한국 교통카드는 일본에서 쓸 수 없습니다. 아이폰이면 지갑 앱에 스이카(Suica)를 추가해 바로 충전해 쓸 수 있고, 실물 카드는 역 발매기에서 스이카·파스모를 사거나 관광객용 'Welcome Suica'를 삽니다. 한 장으로 도쿄·나고야·오사카의 JR과 지하철을 모두 탈 수 있습니다.
A8: 교통 | B8: 교통카드 주의 ① | C8: JR 동일본과 JR 도카이의 경계(아타미)를 넘는 한 번의 승차는 IC카드로 탈 수 없습니다. 이번 일정에는 해당 구간이 없습니다.
A9: 교통 | B9: 교통카드 주의 ② | C9: 시골 버스와 작은 사철은 IC카드가 안 되기도 합니다. 동전과 1,000엔 지폐를 늘 챙기세요 (22일차 고카시 버스 등). 버스는 뒷문으로 타서 정리권을 뽑고, 내릴 때 앞쪽 요금표에서 번호에 맞는 요금을 냅니다.
A10: 교통 | B10: 짐 보내기 (택배) | C10: 편의점이나 숙소 프런트에서 택배(타큐빈)로 짐을 다음 숙소에 보낼 수 있습니다. 보통 다음 날 도착. 하코네처럼 산길을 넘는 날 특히 유용합니다.
A11: 돈 | B11: 결제와 현금 | C11: 한국 신용카드(비자·마스터)는 도시 가게 대부분에서 됩니다. 시골 식당·찻집·버스는 현금만 받는 곳이 많아 1~2만 엔은 늘 지니세요. 현금은 세븐일레븐 ATM에서 해외 카드로 뽑을 수 있습니다.
A12: 돈 | B12: 팁 | C12: 팁 문화가 없습니다. 계산할 때 돈은 카운터의 작은 접시(트레이)에 놓습니다.
A13: 돈 | B13: 면세 (2026년 11월부터 바뀜) | C13: 2026년 11월부터 면세 방식이 바뀌었습니다. 살 때는 세금을 포함한 가격을 내고, 출국할 때 공항 세관에서 물건을 확인받은 뒤 세금을 돌려받습니다. 여권이 필요하고, 면세로 산 물건은 출국 때 바로 보여줄 수 있게 챙기세요.
A14: 돈 | B14: 숙박세 | C14: 도쿄·교토·오사카 등은 1박마다 숙박세가 따로 붙고, 숙소에서 현장 결제하기도 합니다. 교토시는 1인 1박 요금에 따라 200~10,000엔 (2만 엔 미만이면 200~400엔).
A15: 연말연시 | B15: 12월 29일 ~ 1월 3일 휴무 | C15: 많은 식당·가게·관공서·일부 관광지가 문을 닫습니다. 이 기간이 26~31일차와 겹치니 식당은 미리 확인하고, 편의점·체인점을 대안으로 생각해 두세요. 열차는 정상 운행하고 신사는 새해 참배객으로 매우 붐빕니다.
... A34: 안전 | B34: 길 | C34: 차는 왼쪽으로 다닙니다. 길을 건널 때 오른쪽부터 확인하세요. 국도 옆을 걸을 때는 인도가 좁은 곳이 있으니 반사띠나 밝은 옷이 좋습니다.

Sheet 일본어
A1: 상황별 일본어
A2: 빨간 굵은 글씨(한국어 칸) = 꼭 외워 두면 좋은 문장
A4: 분류 | B4: 상황 | C4: 한국어 | D4: 일본어 | E4: 한글 발음 | F4: 팁
A5: 기본 | B5: 인사 | C5: 안녕하세요 (낮) | D5: こんにちは | E5: 곤니치와
A6: 기본 | B6: 인사 | C6: 안녕하세요 (아침) | D6: おはようございます | E6: 오하요- 고자이마스 | F6: 오전 10시 무렵까지
A7: 기본 | B7: 인사 | C7: 안녕하세요 (저녁) | D7: こんばんは | E7: 곰방와
A8: 기본 | B8: 감사 | C8: 감사합니다 | D8: ありがとうございます | E8: 아리가토- 고자이마스 | F8: 가장 많이 쓰게 될 말
A9: 기본 | B9: 부르기·사과 | C9: 저기요 / 죄송합니다 | D9: すみません | E9: 스미마셍 | F9: 사람을 부를 때, 길을 비켜 달라고 할 때, 사과할 때 모두 씀
A10: 기본 | B10: 대답 | C10: 네 / 아니요 | D10: はい / いいえ | E10: 하이 / 이-에
A11: 기본 | B11: 대답 | C11: 괜찮아요 (필요 없어요) | D11: 大丈夫です | E11: 다이죠-부데스 | F11: 봉투·젓가락 등을 거절할 때도 씀
A12: 기본 | B12: 부탁 | C12: 부탁합니다 | D12: お願いします | E12: 오네가이시마스 | F12: 물건을 가리키며 '이거 오네가이시마스'면 대부분 통함
A13: 기본 | B13: 의사소통 | C13: 일본어를 잘 못해요 | D13: 日本語が少ししかできません | E13: 니홍고가 스코시시카 데키마셍
A14: 기본 | B14: 의사소통 | C14: 한 번 더 말해 주세요 | D14: もう一度お願いします | E14: 모- 이치도 오네가이시마스
A15: 기본 | B15: 의사소통 | C15: 천천히 말해 주세요 | D15: ゆっくり話してください | E15: 윳쿠리 하나시테 쿠다사이
A16: 기본 | B16: 의사소통 | C16: 한국에서 왔어요 | D16: 韓国から来ました | E16: 캉코쿠카라 키마시타
A17: 걷기·길 | B17: 길 묻기 | C17: 도카이도 옛길은 어느 쪽이에요? | D17: 旧東海道はどちらですか？ | E17: 규- 토-카이도-와 도치라데스카? | F17: 옛길은 '규-카이도-'라고 함
A18: 걷기·길 | B18: 길 묻기 | C18: ○○까지 걸어서 얼마나 걸려요? | D18: ○○まで歩いてどのくらいかかりますか？ | E18: ○○마데 아루이테 도노쿠라이 카카리마스카?
A19: 걷기·길 | B19: 길 묻기 | C19: 이 길로 가면 ○○에 가요? | D19: この道で○○に行けますか？ | E19: 코노 미치데 ○○니 이케마스카?
A20: 걷기·길 | B20: 길 묻기 | C20: 여기가 지도에서 어디예요? | D20: ここは地図のどこですか？ | E20: 코코와 치즈노 도코데스카? | F20: 휴대폰 지도를 보여 주며
A21: 걷기·길 | B21: 화장실 | C21: 화장실은 어디예요? | D21: トイレはどこですか？ | E21: 토이레와 도코데스카? | F21: 편의점·역·도로 휴게소(미치노에키) 화장실을 쓰면 편함
A22: 걷기·길 | B22: 도카이도 걷기 | C22: 도쿄에서 교토까지 걷고 있어요 | D22: 東京から京都まで歩いています | E22: 도-쿄-카라 쿄-토마데 아루이테 이마스 | F22: 말하면 응원해 주는 사람이 많음
A23: 걷기·길 | B23: 사진 | C23: 사진 찍어 주시겠어요? | D23: 写真を撮っていただけますか？ | E23: 샤싱오 톳테 이타다케마스카?
A24: 걷기·길 | B24: 사진 | C24: 여기서 사진 찍어도 돼요? | D24: ここで写真を撮ってもいいですか？ | E24: 코코데 샤싱오 톳테모 이-데스카? | F24: 신사·절 안에서는 확인하기
A25: 교통 | B25: 표 사기 | C25: ○○까지 표 한 장 주세요 | D25: ○○まで一枚ください | E25: ○○마데 이치마이 쿠다사이 | F25: IC카드(스이카 등)가 있으면 대부분 필요 없음
A26: 교통 | B26: 승강장 | C26: ○○ 가는 열차는 몇 번 승강장이에요? | D26: ○○行きは何番線ですか？ | E26: ○○유키와 난반센데스카?
A27: 교통 | B27: 확인 | C27: 이 열차 ○○에 서요? | D27: この電車は○○に止まりますか？ | E27: 코노 덴샤와 ○○니 토마리마스카? | F27: 쾌속·특급은 작은 역을 지나칠 수 있음
A28: 교통 | B28: 버스 | C28: 이 버스 ○○에 가요? | D28: このバスは○○に行きますか？ | E28: 코노 바스와 ○○니 이키마스카? | F28: 시골 버스는 뒷문으로 타서 정리권을 뽑고, 앞문에서 요금을 냄
A29: 교통 | B29: 버스 | C29: ○○에 도착하면 알려 주세요 | D29: ○○に着いたら教えてください | E29: ○○니 츠이타라 오시에테 쿠다사이
A30: 교통 | B30: 택시 | C30: ○○까지 가 주세요 | D30: ○○までお願いします | E30: ○○마데 오네가이시마스 | F30: 숙소 주소를 보여 주는 게 가장 확실
A31: 교통 | B31: 짐 | C31: 코인 로커는 어디예요? | D31: コインロッカーはどこですか？ | E31: 코인 록카-와 도코데스카?
A32: 음식점 | B32: 입장 | C32: 한 명이에요 | D32: 一人です | E32: 히토리데스 | F32: 손가락 하나를 들어 보여도 됨
A33: 음식점 | B33: 입장 | C33: 자리 있어요? | D33: 空いていますか？ | E33: 아이테 이마스카?
A34: 음식점 | B34: 주문 | C34: 메뉴 주세요 | D34: メニューをください | E34: 메뉴-오 쿠다사이
A35: 음식점 | B35: 주문 | C35: 한국어(영어) 메뉴 있어요? | D35: 韓国語（英語）のメニューはありますか？ | E35: 캉코쿠고(에-고)노 메뉴-와 아리마스카?
A36: 음식점 | B36: 주문 | C36: 추천 메뉴가 뭐예요? | D36: おすすめは何ですか？ | E36: 오스스메와 난데스카? | F36: 지역 명물을 물을 때 가장 유용
A37: 음식점 | B37: 주문 | C37: 이걸로 주세요 | D37: これをください | E37: 코레오 쿠다사이 | F37: 메뉴 사진을 가리키며
A38: 음식점 | B38: 주문 | C38: 이 지역 명물은 뭐예요? | D38: この辺の名物は何ですか？ | E38: 코노 헨노 메-부츠와 난데스카?
A39: 음식점 | B39: 주문 | C39: 생맥주 하나 주세요 | D39: 生ビールを一つください | E39: 나마 비-루오 히토츠 쿠다사이
A40: 음식점 | B40: 주문 | C40: 물 주세요 | D40: お水をください | E40: 오미즈오 쿠다사이 | F40: 대부분 무료로 줌
A41: 음식점 | B41: 주문 | C41: 곱빼기 / 밥 많이 | D41: 大盛りで | E41: 오-모리데 | F41: 걷는 날엔 유용
...

Sheet 경로 좌표
A1: 구글 지도 도보 경로 좌표
A2: 노란 칸 = 숙소가 정해지면 숙소 좌표(위도,경도)로 바꾸는 칸. 바꾸면 그날 지도 링크와 다음 날 출발지(초록 글씨 = 전날 도착지를 자동으로 가져옴)가 함께 바뀝니다.
A3: 좌표 구하는 법: 구글 지도에서 숙소를 길게 누르거나(휴대폰) 오른쪽 클릭(PC)하면 '35.12345, 138.91234' 같은 숫자가 나옵니다. 그대로 복사해 붙여 넣으세요(띄어쓰기는 있어도 됨).
A5: 일차 | B5: 날짜 | C5: 출발 | D5: 출발 좌표 | E5: 경유 1 | F5: 경유 1 좌표 | G5: 경유 2 | H5: 경유 2 좌표 | I5: 경유 3 | J5: 경유 3 좌표 | K5: 도착 | L5: 도착 좌표 | M5: 지도 | N5: 구글 지도 링크 (자동 생성)
A6: 3 | B6: 12/6 | C6: 오이소역 | D6: 35.3114,139.3133 | K6: 호텔 포쉬 오다와라 (숙소) | L6: 35.2559,139.1577 | M6: =HYPERLINK(N6,"지도 열기") -> 지도 열기 | N6: ="https://www.google.com/maps/dir/?api=1&travelmode=walking&origin="&SUBSTITUTE(D6," ","")&"&destination="&SUBSTITUTE(L6," ","")&IF(F6="","","&waypoints="&SUBSTITUTE(F6," ",""))&IF(H6="","","%7C"&SUBSTITUTE(H6," ",""))&IF(J6="","","%7C"&SUBSTITUTE(J6," ","")) -> https://www.google.com/maps/dir/?api=1&travelmode=walking&origin=35.3114,139.3133&destination=35.2559,139.1577
A7: 4 | B7: 12/7 | C7: =K6 -> 호텔 포쉬 오다와라 (숙소) | D7: =L6 -> 35.2559,139.1577 | E7: 하코네유모토역 | F7: 35.2333,139.1036 | G7: 하타주쿠 (돌길 입구) | H7: 35.213,139.0631 | I7: 아마자케차야 | J7: 35.2022,139.0488 | K7: RoheN ASHINOKO (숙소) | L7: 35.2041,139.0327 | M7: =HYPERLINK(N7,"지도 열기") -> 지도 열기 | N7: ="https://www.google.com/maps/dir/?api=1&travelmode=walking&origin="&SUBSTITUTE(D7," ","")&"&destination="&SUBSTITUTE(L7," ","")&IF(F7="","","&waypoints="&SUBSTITUTE(F7," ",""))&IF(H7="","","%7C"&SUBSTITUTE(H7," ",""))&IF(J7="","","%7C"&SUBSTITUTE(J7," ","")) -> https://www.google.com/maps/dir/?api=1&travelmode=walking&origin=35.2559,139.1577&destination=35.2041,139.0327&waypoints=35.2333,139.1036%7C35.213,139.0631%7C35.2022,139.0488
A8: 6 | B8: 12/9 | C8: =K7 -> RoheN ASHINOKO (숙소) | D8: =L7 -> 35.2041,139.0327 | E8: 하코네 관소 | F8: 35.1924,139.0262 | G8: 하코네 고개 | H8: 35.1824,139.014 | I8: 야마나카성터 | J8: 35.1566,138.9943 | K8: Hotel Gee Haive (숙소) | L8: 35.1243,138.9081 | M8: =HYPERLINK(N8,"지도 열기") -> 지도 열기 | N8: ="https://www.google.com/maps/dir/?api=1&travelmode=walking&origin="&SUBSTITUTE(D8," ","")&"&destination="&SUBSTITUTE(L8," ","")&IF(F8="","","&waypoints="&SUBSTITUTE(F8," ",""))&IF(H8="","","%7C"&SUBSTITUTE(H8," ",""))&IF(J8="","","%7C"&SUBSTITUTE(J8," ","")) -> https://www.google.com/maps/dir/?api=1&travelmode=walking&origin=35.2041,139.0327&destination=35.1243,138.9081&waypoints=35.1924,139.0262%7C35.1824,139.014%7C35.1566,138.9943
A9: 7 | B9: 12/10 | C9: =K8 -> Hotel Gee Haive (숙소) | D9: =L8 -> 35.1243,138.9081 | E9: 누마즈주쿠 본진 터 | F9: 35.095,138.8564 | G9: 센본마쓰바라 | H9: 35.1184,138.8072 | I9: 하라역 | J9: 35.1249,138.7938 | K9: 호텔 니시무라 (숙소) | L9: 35.1604,138.6768 | M9: =HYPERLINK(N9,"지도 열기") -> 지도 열기 | N9: ="https://www.google.com/maps/dir/?api=1&travelmode=walking&origin="&SUBSTITUTE(D9," ","")&"&destination="&SUBSTITUTE(L9," ","")&IF(F9="","","&waypoints="&SUBSTITUTE(F9," ",""))&IF(H9="","","%7C"&SUBSTITUTE(H9," ",""))&IF(J9="","","%7C"&SUBSTITUTE(J9," ","")) -> https://www.google.com/maps/dir/?api=1&travelmode=walking&origin=35.1243,138.9081&destination=35.1604,138.6768&waypoints=35.095,138.8564%7C35.1184,138.8072%7C35.1249,138.7938
A10: 8 | B10: 12/11 | C10: =K9 -> 호텔 니시무라 (숙소) | D10: =L9 -> 35.1604,138.6768 | E10: 후지강 다리 | F10: 35.1549,138.6239 | G10: 유이 본진 공원 | H10: 35.1076,138.5672 | I10: 삿타 고개 | J10: 35.0715,138.5413 | K10: 쿠어 앤 호텔 스루가 (숙소) | L10: 35.0569,138.5331 | M10: =HYPERLINK(N10,"지도 열기") -> 지도 열기 | N10: ="https://www.google.com/maps/dir/?api=1&travelmode=walking&origin="&SUBSTITUTE(D10," ","")&"&destination="&SUBSTITUTE(L10," ","")&IF(F10="","","&waypoints="&SUBSTITUTE(F10," ",""))&IF(H10="","","%7C"&SUBSTITUTE(H10," ",""))&IF(J10="","","%7C"&SUBSTITUTE(J10," ","")) -> https://www.google.com/maps/dir/?api=1&travelmode=walking&origin=35.1604,138.6768&destination=35.0569,138.5331&waypoints=35.1549,138.6239%7C35.1076,138.5672%7C35.0715,138.5413
A11: 10 | B11: 12/13 | C11: =K10 -> 쿠어 앤 호텔 스루가 (숙소) | D11: =L10 -> 35.0569,138.5331 | E11: 시미즈역 (에지리) | F11: 35.0232,138.4889 | G11: 구사나기 일리총 | H11: 35.0059,138.453 | I11: 시즈오카 후다노쓰지 (후추주쿠) | J11: 34.9751,138.3816 | K11: 호텔 가든 스퀘어 시즈오카 (숙소) | L11: 34.9721,138.3849 | M11: =HYPERLINK(N11,"지도 열기") -> 지도 열기 | N11: ="https://www.google.com/maps/dir/?api=1&travelmode=walking&origin="&SUBSTITUTE(D11," ","")&"&destination="&SUBSTITUTE(L11," ","")&IF(F11="","","&waypoints="&SUBSTITUTE(F11," ",""))&IF(H11="","","%7C"&SUBSTITUTE(H11," ",""))&IF(J11="","","%7C"&SUBSTITUTE(J11," ","")) -> https://www.google.com/maps/dir/?api=1&travelmode=walking&origin=35.0569,138.5331&destination=34.9721,138.3849&waypoints=35.0232,138.4889%7C35.0059,138.453%7C34.9751,138.3816
A12: 11 | B12: 12/14 | C12: =K11 -> 호텔 가든 스퀘어 시즈오카 (숙소) | D12: =L11 -> 34.9721,138.3849 | E12: 마리코 조지야 | F12: 34.9522,138.3341 | G12: 우쓰노야 오하오리야 | H12: 34.936,138.3042 | I12: 오카베 가시와야 | J12: 34.9194,138.2827 | K12: 호텔 슈퍼 도마리 (숙소) | L12: 34.8479,138.2561 | M12: =HYPERLINK(N12,"지도 열기") -> 지도 열기 | N12: ="https://www.google.com/maps/dir/?api=1&travelmode=walking&origin="&SUBSTITUTE(D12," ","")&"&destination="&SUBSTITUTE(L12," ","")&IF(F12="","","&waypoints="&SUBSTITUTE(F12," ",""))&IF(H12="","","%7C"&SUBSTITUTE(H12," ",""))&IF(J12="","","%7C"&SUBSTITUTE(J12," ","")) -> https://www.google.com/maps/dir/?api=1&travelmode=walking&origin=34.9721,138.3849&destination=34.8479,138.2561&waypoints=34.9522,138.3341%7C34.936,138.3042%7C34.9194,138.2827
A13: 12 | B13: 12/15 | C13: =K12 -> 호텔 슈퍼 도마리 (숙소) | D13: =L12 -> 34.8479,138.2561 | K13: 호텔 루트인 시마다 에키마에 (숙소) | L13: 34.8328,138.1776 | M13: =HYPERLINK(N13,"지도 열기") -> 지도 열기 | N13: ="https://www.google.com/maps/dir/?api=1&travelmode=walking&origin="&SUBSTITUTE(D13," ","")&"&destination="&SUBSTITUTE(L13," ","")&IF(F13="","","&waypoints="&SUBSTITUTE(F13," ",""))&IF(H13="","","%7C"&SUBSTITUTE(H13," ",""))&IF(J13="","","%7C"&SUBSTITUTE(J13," ","")) -> https://www.google.com/maps/dir/?api=1&travelmode=walking&origin=34.8479,138.2561&destination=34.8328,138.1776
A14: 13 | B14: 12/16 | C14: =K13 -> 호텔 루트인 시마다 에키마에 (숙소) | D14: =L13 -> 34.8328,138.1776 | E14: 호라이교 | F14: 34.825,138.1847 | G14: 가나야 돌길 | H14: 34.8156,138.1239 | I14: 닛사카 가와사카야 | J14: 34.8027,138.0762 | K14: 도미 인 익스프레스 가케가와 (숙소) | L14: 34.7732,138.0184 | M14: =HYPERLINK(N14,"지도 열기") -> 지도 열기 | N14: ="https://www.google.com/maps/dir/?api=1&travelmode=walking&origin="&SUBSTITUTE(D14," ","")&"&destination="&SUBSTITUTE(L14," ","")&IF(F14="","","&waypoints="&SUBSTITUTE(F14," ",""))&IF(H14="","","%7C"&SUBSTITUTE(H14," ",""))&IF(J14="","","%7C"&SUBSTITUTE(J14," ","")) -> https://www.google.com/maps/dir/?api=1&travelmode=walking&origin=34.8328,138.1776&destination=34.7732,138.0184&waypoints=34.825,138.1847%7C34.8156,138.1239%7C34.8027,138.0762
A15: 14 | B15: 12/17 | C15: 하마마쓰역 | D15: 34.7042,137.7345 | E15: 마이사카 소나무 가로수길 | F15: 34.6837,137.6222 | G15: 벤텐지마 | H15: 34.6907,137.6066 | I15: 아라이 관소 | J15: 34.6947,137.5613 | K15: 호텔 난반 하마나코 (숙소) | L15: 34.7147,137.5456 | M15: =HYPERLINK(N15,"지도 열기") -> 지도 열기 | N15: ="https://www.google.com/maps/dir/?api=1&travelmode=walking&origin="&SUBSTITUTE(D15," ","")&"&destination="&SUBSTITUTE(L15," ","")&IF(F15="","","&waypoints="&SUBSTITUTE(F15," ",""))&IF(H15="","","%7C"&SUBSTITUTE(H15," ",""))&IF(J15="","","%7C"&SUBSTITUTE(J15," ","")) -> https://www.google.com/maps/dir/?api=1&travelmode=walking&origin=34.7042,137.7345&destination=34.7147,137.5456&waypoints=34.6837,137.6222%7C34.6907,137.6066%7C34.6947,137.5613
A16: 16 | B16: 12/19 | C16: =K15 -> 호텔 난반 하마나코 (숙소) | D16: =L15 -> 34.7147,137.5456 | E16: 시라스카 (시오미자카) | F16: 34.6815,137.5112 | G16: 후타가와주쿠 본진 | H16: 34.7234,137.4499 | K16: 호텔 어소시아 도요하시 (숙소) | L16: 34.7632,137.3827 | M16: =HYPERLINK(N16,"지도 열기") -> 지도 열기 | N16: ="https://www.google.com/maps/dir/?api=1&travelmode=walking&origin="&SUBSTITUTE(D16," ","")&"&destination="&SUBSTITUTE(L16," ","")&IF(F16="","","&waypoints="&SUBSTITUTE(F16," ",""))&IF(H16="","","%7C"&SUBSTITUTE(H16," ",""))&IF(J16="","","%7C"&SUBSTITUTE(J16," ","")) -> https://www.google.com/maps/dir/?api=1&travelmode=walking&origin=34.7147,137.5456&destination=34.7632,137.3827&waypoints=34.6815,137.5112%7C34.7234,137.4499
A17: 17 | B17: 12/20 | C17: =K16 -> 호텔 어소시아 도요하시 (숙소) | D17: =L16 -> 34.7632,137.3827 | E17: 고유 소나무 가로수길 | F17: 34.8511,137.3125 | K17: 메이덴아카사카역 | L17: 34.8591,137.3114 | M17: =HYPERLINK(N17,"지도 열기") -> 지도 열기 | N17: ="https://www.google.com/maps/dir/?api=1&travelmode=walking&origin="&SUBSTITUTE(D17," ","")&"&destination="&SUBSTITUTE(L17," ","")&IF(F17="","","&waypoints="&SUBSTITUTE(F17," ",""))&IF(H17="","","%7C"&SUBSTITUTE(H17," ",""))&IF(J17="","","%7C"&SUBSTITUTE(J17," ","")) -> https://www.google.com/maps/dir/?api=1&travelmode=walking&origin=34.7632,137.3827&destination=34.8591,137.3114&waypoints=34.8511,137.3125
A18: 18 | B18: 12/21 | C18: 메이덴아카사카역 | D18: 34.8591,137.3114 | E18: 후지카와주쿠 본진 터 | F18: 34.9113,137.2221 | G18: 오카자키성 | H18: 34.9563,137.1588 | K18: 호텔 라이브맥스 오카자키 (숙소) | L18: 34.9557,137.169 | M18: =HYPERLINK(N18,"지도 열기") -> 지도 열기 | N18: ="https://www.google.com/maps/dir/?api=1&travelmode=walking&origin="&SUBSTITUTE(D18," ","")&"&destination="&SUBSTITUTE(L18," ","")&IF(F18="","","&waypoints="&SUBSTITUTE(F18," ",""))&IF(H18="","","%7C"&SUBSTITUTE(H18," ",""))&IF(J18="","","%7C"&SUBSTITUTE(J18," ","")) -> https://www.google.com/maps/dir/?api=1&travelmode=walking&origin=34.8591,137.3114&destination=34.9557,137.169&waypoints=34.9113,137.2221%7C34.9563,137.1588
A19: 19 | B19: 12/22 | C19: 지류역 | D19: 35.0059,137.0397 | E19: 아리마쓰 옛 거리 | F19: 35.0674,136.9701 | G19: 나루미역 | H19: 35.0785,136.9507 | K19: 아쓰타 신궁 | L19: 35.1243,136.9089 | M19: =HYPERLINK(N19,"지도 열기") -> 지도 열기 | N19: ="https://www.google.com/maps/dir/?api=1&travelmode=walking&origin="&SUBSTITUTE(D19," ","")&"&destination="&SUBSTITUTE(L19," ","")&IF(F19="","","&waypoints="&SUBSTITUTE(F19," ",""))&IF(H19="","","%7C"&SUBSTITUTE(H19," ",""))&IF(J19="","","%7C"&SUBSTITUTE(J19," ","")) -> https://www.google.com/maps/dir/?api=1&travelmode=walking&origin=35.0059,137.0397&destination=35.1243,136.9089&waypoints=35.0674,136.9701%7C35.0785,136.9507
A20: 21 | B20: 12/24 | C20: 가사도역 | D20: 34.8905,136.5303 | E20: 쇼노주쿠 자료관 | F20: 34.8846,136.5256 | G20: 가메야마성 | H20: 34.8561,136.4507 | K20: 칸데오 호텔 가메야마 (숙소) | L20: 34.8567,136.4112 | M20: =HYPERLINK(N20,"지도 열기") -> 지도 열기 | N20: ="https://www.google.com/maps/dir/?api=1&travelmode=walking&origin="&SUBSTITUTE(D20," ","")&"&destination="&SUBSTITUTE(L20," ","")&IF(F20="","","&waypoints="&SUBSTITUTE(F20," ",""))&IF(H20="","","%7C"&SUBSTITUTE(H20," ",""))&IF(J20="","","%7C"&SUBSTITUTE(J20," ","")) -> https://www.google.com/maps/dir/?api=1&travelmode=walking&origin=34.8905,136.5303&destination=34.8567,136.4112&waypoints=34.8846,136.5256%7C34.8561,136.4507
A21: 22 | B21: 12/25 | C21: =K20 -> 칸데오 호텔 가메야마 (숙소) | D21: =L20 -> 34.8567,136.4112 | E21: 세키주쿠 옛 거리 | F21: 34.8526,136.3918 | G21: 사카시타주쿠 | H21: 34.8885,136.3543 | I21: 스즈카 고개 | J21: 34.8939,136.3368 | K21: 쓰치야마 덴마칸 | L21: 34.9355,136.2833 | M21: =HYPERLINK(N21,"지도 열기") -> 지도 열기 | N21: ="https://www.google.com/maps/dir/?api=1&travelmode=walking&origin="&SUBSTITUTE(D21," ","")&"&destination="&SUBSTITUTE(L21," ","")&IF(F21="","","&waypoints="&SUBSTITUTE(F21," ",""))&IF(H21="","","%7C"&SUBSTITUTE(H21," ",""))&IF(J21="","","%7C"&SUBSTITUTE(J21," ","")) -> https://www.google.com/maps/dir/?api=1&travelmode=walking&origin=34.8567,136.4112&destination=34.9355,136.2833&waypoints=34.8526,136.3918%7C34.8885,136.3543%7C34.8939,136.3368
A22: 23 | B22: 12/26 | C22: 미나쿠치 센추리 호텔 (숙소) | D22: 34.9778,136.173 | E22: 이시베역 | F22: 35.0177,136.053 | G22: 구사쓰주쿠 본진 | H22: 35.0178,135.9603 | K22: 호텔 보스턴 플라자 구사쓰 (숙소) | L22: 35.0228,135.9607 | M22: =HYPERLINK(N22,"지도 열기") -> 지도 열기 | N22: ="https://www.google.com/maps/dir/?api=1&travelmode=walking&origin="&SUBSTITUTE(D22," ","")&"&destination="&SUBSTITUTE(L22," ","")&IF(F22="","","&waypoints="&SUBSTITUTE(F22," ",""))&IF(H22="","","%7C"&SUBSTITUTE(H22," ",""))&IF(J22="","","%7C"&SUBSTITUTE(J22," ","")) -> https://www.google.com/maps/dir/?api=1&travelmode=walking&origin=34.9778,136.173&destination=35.0228,135.9607&waypoints=35.0177,136.053%7C35.0178,135.9603
A23: 24 | B23: 12/27 | C23: =K22 -> 호텔 보스턴 플라자 구사쓰 (숙소) | D23: =L22 -> 35.0228,135.9607 | E23: 세타 가라하시 | F23: 34.973,135.9067 | K23: 르 락 호텔 오쓰 이시야마 (숙소) | L23: 34.9786,135.9005 | M23: =HYPERLINK(N23,"지도 열기") -> 지도 열기 | N23: ="https://www.google.com/maps/dir/?api=1&travelmode=walking&origin="&SUBSTITUTE(D23," ","")&"&destination="&SUBSTITUTE(L23," ","")&IF(F23="","","&waypoints="&SUBSTITUTE(F23," ",""))&IF(H23="","","%7C"&SUBSTITUTE(H23," ",""))&IF(J23="","","%7C"&SUBSTITUTE(J23," ","")) -> https://www.google.com/maps/dir/?api=1&travelmode=walking&origin=35.0228,135.9607&destination=34.9786,135.9005&waypoints=34.973,135.9067
